Workbook

Sheet DOH
B2: DOH Total – Visão João Pessoa x Araucária
B5: 1. DOH Total por CD
B6: CD | C6: Estoque | D6: Demanda | E6: DOH
B7: Araucária | C7: =SUMIFS(Base!$P$3:$P$980,Base!$J$3:$J$980,"Ara") -> 41627.845 | D7: =SUMIFS(Base!$L$3:$L$980,Base!$J$3:$J$980,"Ara") -> 3289.4847 | E7: =IFERROR(C7/D7,0) -> 12.654823
B8: João Pessoa | C8: =SUMIFS(Base!$P$3:$P$980,Base!$J$3:$J$980,"Jpe") -> 19446.247 | D8: =SUMIFS(Base!$L$3:$L$980,Base!$J$3:$J$980,"Jpe") -> 1749.4654 | E8: =IFERROR(C8/D8,0) -> 11.115537
B9: Total Geral | C9: =SUM(C7:C8) -> 61074.092 | D9: =SUM(D7:D8) -> 5038.9501 | E9: =IFERROR(C9/D9,0) -> 12.1204
B11: 2. DOH Total por Categoria
C13: DOH (limitado à PE)
B14: Categoria | C14: Ara | D14: Jpe | E14: Total
B15: =IFERROR(INDEX(Base!$G$3:$G$980,MATCH(SMALL(Base!$R$3:$R$980,1),Base!$R$3:$R$980,0)),"") -> PÃES | C15: =IF($B15="","",IFERROR(SUMIFS(Base!$P$3:$P$980,Base!$G$3:$G$980,$B15,Base!$J$3:$J$980,"Ara")/SUMIFS(Base!$L$3:$L$980,Base!$G$3:$G$980,$B15,Base!$J$3:$J$980,"Ara"),"")) -> 7.8057792 | D15: =IF($B15="","",IFERROR(SUMIFS(Base!$P$3:$P$980,Base!$G$3:$G$980,$B15,Base!$J$3:$J$980,"Jpe")/SUMIFS(Base!$L$3:$L$980,Base!$G$3:$G$980,$B15,Base!$J$3:$J$980,"Jpe"),"")) -> 4.9281657 | E15: =IF($B15="","",IFERROR(SUMIFS(Base!$P$3:$P$980,Base!$G$3:$G$980,$B15)/SUMIFS(Base!$L$3:$L$980,Base!$G$3:$G$980,$B15),"")) -> 6.7995767
B16: =IFERROR(INDEX(Base!$G$3:$G$980,MATCH(SMALL(Base!$R$3:$R$980,2),Base!$R$3:$R$980,0)),"") -> PROTEINAS | C16: =IF($B16="","",IFERROR(SUMIFS(Base!$P$3:$P$980,Base!$G$3:$G$980,$B16,Base!$J$3:$J$980,"Ara")/SUMIFS(Base!$L$3:$L$980,Base!$G$3:$G$980,$B16,Base!$J$3:$J$980,"Ara"),"")) -> 9.9739293 | D16: =IF($B16="","",IFERROR(SUMIFS(Base!$P$3:$P$980,Base!$G$3:$G$980,$B16,Base!$J$3:$J$980,"Jpe")/SUMIFS(Base!$L$3:$L$980,Base!$G$3:$G$980,$B16,Base!$J$3:$J$980,"Jpe"),"")) -> 9.6034716 | E16: =IF($B16="","",IFERROR(SUMIFS(Base!$P$3:$P$980,Base!$G$3:$G$980,$B16)/SUMIFS(Base!$L$3:$L$980,Base!$G$3:$G$980,$B16),"")) -> 9.8520174
B17: =IFERROR(INDEX(Base!$G$3:$G$980,MATCH(SMALL(Base!$R$3:$R$980,3),Base!$R$3:$R$980,0)),"") -> LÁCTEOS | C17: =IF($B17="","",IFERROR(SUMIFS(Base!$P$3:$P$980,Base!$G$3:$G$980,$B17,Base!$J$3:$J$980,"Ara")/SUMIFS(Base!$L$3:$L$980,Base!$G$3:$G$980,$B17,Base!$J$3:$J$980,"Ara"),"")) -> 9.6950832 | D17: =IF($B17="","",IFERROR(SUMIFS(Base!$P$3:$P$980,Base!$G$3:$G$980,$B17,Base!$J$3:$J$980,"Jpe")/SUMIFS(Base!$L$3:$L$980,Base!$G$3:$G$980,$B17,Base!$J$3:$J$980,"Jpe"),"")) -> 12.350611 | E17: =IF($B17="","",IFERROR(SUMIFS(Base!$P$3:$P$980,Base!$G$3:$G$980,$B17)/SUMIFS(Base!$L$3:$L$980,Base!$G$3:$G$980,$B17),"")) -> 10.341619
B18: =IFERROR(INDEX(Base!$G$3:$G$980,MATCH(SMALL(Base!$R$3:$R$980,4),Base!$R$3:$R$980,0)),"") -> SOBREMESAS | C18: =IF($B18="","",IFERROR(SUMIFS(Base!$P$3:$P$980,Base!$G$3:$G$980,$B18,Base!$J$3:$J$980,"Ara")/SUMIFS(Base!$L$3:$L$980,Base!$G$3:$G$980,$B18,Base!$J$3:$J$980,"Ara"),"")) -> 11.291437 | D18: =IF($B18="","",IFERROR(SUMIFS(Base!$P$3:$P$980,Base!$G$3:$G$980,$B18,Base!$J$3:$J$980,"Jpe")/SUMIFS(Base!$L$3:$L$980,Base!$G$3:$G$980,$B18,Base!$J$3:$J$980,"Jpe"),"")) -> 13.765229 | E18: =IF($B18="","",IFERROR(SUMIFS(Base!$P$3:$P$980,Base!$G$3:$G$980,$B18)/SUMIFS(Base!$L$3:$L$980,Base!$G$3:$G$980,$B18),"")) -> 12.513607
B19: =IFERROR(INDEX(Base!$G$3:$G$980,MATCH(SMALL(Base!$R$3:$R$980,5),Base!$R$3:$R$980,0)),"") -> EMBALAGENS | C19: =IF($B19="","",IFERROR(SUMIFS(Base!$P$3:$P$980,Base!$G$3:$G$980,$B19,Base!$J$3:$J$980,"Ara")/SUMIFS(Base!$L$3:$L$980,Base!$G$3:$G$980,$B19,Base!$J$3:$J$980,"Ara"),"")) -> 16.249838 | D19: =IF($B19="","",IFERROR(SUMIFS(Base!$P$3:$P$980,Base!$G$3:$G$980,$B19,Base!$J$3:$J$980,"Jpe")/SUMIFS(Base!$L$3:$L$980,Base!$G$3:$G$980,$B19,Base!$J$3:$J$980,"Jpe"),"")) -> 11.968507 | E19: =IF($B19="","",IFERROR(SUMIFS(Base!$P$3:$P$980,Base!$G$3:$G$980,$B19)/SUMIFS(Base!$L$3:$L$980,Base!$G$3:$G$980,$B19),"")) -> 14.458771
B20: =IFERROR(INDEX(Base!$G$3:$G$980,MATCH(SMALL(Base!$R$3:$R$980,6),Base!$R$3:$R$980,0)),"") -> HORTIFRUTI | C20: =IF($B20="","",IFERROR(SUMIFS(Base!$P$3:$P$980,Base!$G$3:$G$980,$B20,Base!$J$3:$J$980,"Ara")/SUMIFS(Base!$L$3:$L$980,Base!$G$3:$G$980,$B20,Base!$J$3:$J$980,"Ara"),"")) -> 13.729384 | D20: =IF($B20="","",IFERROR(SUMIFS(Base!$P$3:$P$980,Base!$G$3:$G$980,$B20,Base!$J$3:$J$980,"Jpe")/SUMIFS(Base!$L$3:$L$980,Base!$G$3:$G$980,$B20,Base!$J$3:$J$980,"Jpe"),"")) -> 16.630169 | E20: =IF($B20="","",IFERROR(SUMIFS(Base!$P$3:$P$980,Base!$G$3:$G$980,$B20)/SUMIFS(Base!$L$3:$L$980,Base!$G$3:$G$980,$B20),"")) -> 14.610594
B21: =IFERROR(INDEX(Base!$G$3:$G$980,MATCH(SMALL(Base!$R$3:$R$980,7),Base!$R$3:$R$980,0)),"") -> CONDIMENTOS | C21: =IF($B21="","",IFERROR(SUMIFS(Base!$P$3:$P$980,Base!$G$3:$G$980,$B21,Base!$J$3:$J$980,"Ara")/SUMIFS(Base!$L$3:$L$980,Base!$G$3:$G$980,$B21,Base!$J$3:$J$980,"Ara"),"")) -> 17.780974 | D21: =IF($B21="","",IFERROR(SUMIFS(Base!$P$3:$P$980,Base!$G$3:$G$980,$B21,Base!$J$3:$J$980,"Jpe")/SUMIFS(Base!$L$3:$L$980,Base!$G$3:$G$980,$B21,Base!$J$3:$J$980,"Jpe"),"")) -> 13.033671 | E21: =IF($B21="","",IFERROR(SUMIFS(Base!$P$3:$P$980,Base!$G$3:$G$980,$B21)/SUMIFS(Base!$L$3:$L$980,Base!$G$3:$G$980,$B21),"")) -> 16.130461
B22: =IFERROR(INDEX(Base!$G$3:$G$980,MATCH(SMALL(Base!$R$3:$R$980,8),Base!$R$3:$R$980,0)),"") -> MOLHOS | C22: =IF($B22="","",IFERROR(SUMIFS(Base!$P$3:$P$980,Base!$G$3:$G$980,$B22,Base!$J$3:$J$980,"Ara")/SUMIFS(Base!$L$3:$L$980,Base!$G$3:$G$980,$B22,Base!$J$3:$J$980,"Ara"),"")) -> 19.063392 | D22: =IF($B22="","",IFERROR(SUMIFS(Base!$P$3:$P$980,Base!$G$3:$G$980,$B22,Base!$J$3:$J$980,"Jpe")/SUMIFS(Base!$L$3:$L$980,Base!$G$3:$G$980,$B22,Base!$J$3:$J$980,"Jpe"),"")) -> 13.415925 | E22: =IF($B22="","",IFERROR(SUMIFS(Base!$P$3:$P$980,Base!$G$3:$G$980,$B22)/SUMIFS(Base!$L$3:$L$980,Base!$G$3:$G$980,$B22),"")) -> 17.046129
B23: =IFERROR(INDEX(Base!$G$3:$G$980,MATCH(SMALL(Base!$R$3:$R$980,9),Base!$R$3:$R$980,0)),"") -> BEBIDAS | C23: =IF($B23="","",IFERROR(SUMIFS(Base!$P$3:$P$980,Base!$G$3:$G$980,$B23,Base!$J$3:$J$980,"Ara")/SUMIFS(Base!$L$3:$L$980,Base!$G$3:$G$980,$B23,Base!$J$3:$J$980,"Ara"),"")) -> 19.542407 | D23: =IF($B23="","",IFERROR(SUMIFS(Base!$P$3:$P$980,Base!$G$3:$G$980,$B23,Base!$J$3:$J$980,"Jpe")/SUMIFS(Base!$L$3:$L$980,Base!$G$3:$G$980,$B23,Base!$J$3:$J$980,"Jpe"),"")) -> 17.2076 | E23: =IF($B23="","",IFERROR(SUMIFS(Base!$P$3:$P$980,Base!$G$3:$G$980,$B23)/SUMIFS(Base!$L$3:$L$980,Base!$G$3:$G$980,$B23),"")) -> 18.783915
B24: Total Geral | C24: =IFERROR(SUMIFS(Base!$P$3:$P$980,Base!$J$3:$J$980,"Ara")/SUMIFS(Base!$L$3:$L$980,Base!$J$3:$J$980,"Ara"),"") -> 12.654823 | D24: =IFERROR(SUMIFS(Base!$P$3:$P$980,Base!$J$3:$J$980,"Jpe")/SUMIFS(Base!$L$3:$L$980,Base!$J$3:$J$980,"Jpe"),"") -> 11.115537 | E24: =IFERROR(SUM(Base!$P$3:$P$980)/SUM(Base!$L$3:$L$980),"") -> 12.1204
B27: 3. DOH Total por Fornecedor (ordena sozinho: mais crítico primeiro)
C28: DOH (limitado à PE)
B29: Fornecedor | C29: Ara | D29: Jpe | E29: Total
B30: =IFERROR(INDEX(Base!$I$3:$I$980,MATCH(SMALL(Base!$Q$3:$Q$980,1),Base!$Q$3:$Q$980,0)),"") -> AB BRASIL | C30: =IF($B30="","",IFERROR(SUMIFS(Base!$P$3:$P$980,Base!$I$3:$I$980,$B30,Base!$J$3:$J$980,"Ara")/SUMIFS(Base!$L$3:$L$980,Base!$I$3:$I$980,$B30,Base!$J$3:$J$980,"Ara"),"")) -> 0 | D30: =IF($B30="","",IFERROR(SUMIFS(Base!$P$3:$P$980,Base!$I$3:$I$980,$B30,Base!$J$3:$J$980,"Jpe")/SUMIFS(Base!$L$3:$L$980,Base!$I$3:$I$980,$B30,Base!$J$3:$J$980,"Jpe"),"")) -> -0.48722277 | E30: =IF($B30="","",IFERROR(SUMIFS(Base!$P$3:$P$980,Base!$I$3:$I$980,$B30)/SUMIFS(Base!$L$3:$L$980,Base!$I$3:$I$980,$B30),"")) -> -0.2290841
B31: =IFERROR(INDEX(Base!$I$3:$I$980,MATCH(SMALL(Base!$Q$3:$Q$980,2),Base!$Q$3:$Q$980,0)),"") -> CELLIER | C31: =IF($B31="","",IFERROR(SUMIFS(Base!$P$3:$P$980,Base!$I$3:$I$980,$B31,Base!$J$3:$J$980,"Ara")/SUMIFS(Base!$L$3:$L$980,Base!$I$3:$I$980,$B31,Base!$J$3:$J$980,"Ara"),"")) -> 0.94362611 | D31: =IF($B31="","",IFERROR(SUMIFS(Base!$P$3:$P$980,Base!$I$3:$I$980,$B31,Base!$J$3:$J$980,"Jpe")/SUMIFS(Base!$L$3:$L$980,Base!$I$3:$I$980,$B31,Base!$J$3:$J$980,"Jpe"),"")) -> 10.623585 | E31: =IF($B31="","",IFERROR(SUMIFS(Base!$P$3:$P$980,Base!$I$3:$I$980,$B31)/SUMIFS(Base!$L$3:$L$980,Base!$I$3:$I$980,$B31),"")) -> 5.8698303
B32: =IFERROR(INDEX(Base!$I$3:$I$980,MATCH(SMALL(Base!$Q$3:$Q$980,3),Base!$Q$3:$Q$980,0)),"") -> BIMBO | C32: =IF($B32="","",IFERROR(SUMIFS(Base!$P$3:$P$980,Base!$I$3:$I$980,$B32,Base!$J$3:$J$980,"Ara")/SUMIFS(Base!$L$3:$L$980,Base!$I$3:$I$980,$B32,Base!$J$3:$J$980,"Ara"),"")) -> 7.8057792 | D32: =IF($B32="","",IFERROR(SUMIFS(Base!$P$3:$P$980,Base!$I$3:$I$980,$B32,Base!$J$3:$J$980,"Jpe")/SUMIFS(Base!$L$3:$L$980,Base!$I$3:$I$980,$B32,Base!$J$3:$J$980,"Jpe"),"")) -> 4.9281657 | E32: =IF($B32="","",IFERROR(SUMIFS(Base!$P$3:$P$980,Base!$I$3:$I$980,$B32)/SUMIFS(Base!$L$3:$L$980,Base!$I$3:$I$980,$B32),"")) -> 6.7995767
B33: =IFERROR(INDEX(Base!$I$3:$I$980,MATCH(SMALL(Base!$Q$3:$Q$980,4),Base!$Q$3:$Q$980,0)),"") -> CARINO | C33: =IF($B33="","",IFERROR(SUMIFS(Base!$P$3:$P$980,Base!$I$3:$I$980,$B33,Base!$J$3:$J$980,"Ara")/SUMIFS(Base!$L$3:$L$980,Base!$I$3:$I$980,$B33,Base!$J$3:$J$980,"Ara"),"")) -> 1.1780091 | D33: =IF($B33="","",IFERROR(SUMIFS(Base!$P$3:$P$980,Base!$I$3:$I$980,$B33,Base!$J$3:$J$980,"Jpe")/SUMIFS(Base!$L$3:$L$980,Base!$I$3:$I$980,$B33,Base!$J$3:$J$980,"Jpe"),"")) -> 13.53477 | E33: =IF($B33="","",IFERROR(SUMIFS(Base!$P$3:$P$980,Base!$I$3:$I$980,$B33)/SUMIFS(Base!$L$3:$L$980,Base!$I$3:$I$980,$B33),"")) -> 6.8550017
B34: =IFERROR(INDEX(Base!$I$3:$I$980,MATCH(SMALL(Base!$Q$3:$Q$980,5),Base!$Q$3:$Q$980,0)),"") -> JBS | C34: =IF($B34="","",IFERROR(SUMIFS(Base!$P$3:$P$980,Base!$I$3:$I$980,$B34,Base!$J$3:$J$980,"Ara")/SUMIFS(Base!$L$3:$L$980,Base!$I$3:$I$980,$B34,Base!$J$3:$J$980,"Ara"),"")) -> 7 | D34: =IF($B34="","",IFERROR(SUMIFS(Base!$P$3:$P$980,Base!$I$3:$I$980,$B34,Base!$J$3:$J$980,"Jpe")/SUMIFS(Base!$L$3:$L$980,Base!$I$3:$I$980,$B34,Base!$J$3:$J$980,"Jpe"),"")) -> 7 | E34: =IF($B34="","",IFERROR(SUMIFS(Base!$P$3:$P$980,Base!$I$3:$I$980,$B34)/SUMIFS(Base!$L$3:$L$980,Base!$I$3:$I$980,$B34),"")) -> 7
B35: =IFERROR(INDEX(Base!$I$3:$I$980,MATCH(SMALL(Base!$Q$3:$Q$980,6),Base!$Q$3:$Q$980,0)),"") -> DOHLER 01 | C35: =IF($B35="","",IFERROR(SUMIFS(Base!$P$3:$P$980,Base!$I$3:$I$980,$B35,Base!$J$3:$J$980,"Ara")/SUMIFS(Base!$L$3:$L$980,Base!$I$3:$I$980,$B35,Base!$J$3:$J$980,"Ara"),"")) -> 10.755817 | D35: =IF($B35="","",IFERROR(SUMIFS(Base!$P$3:$P$980,Base!$I$3:$I$980,$B35,Base!$J$3:$J$980,"Jpe")/SUMIFS(Base!$L$3:$L$980,Base!$I$3:$I$980,$B35,Base!$J$3:$J$980,"Jpe"),"")) -> 3.6108932 | E35: =IF($B35="","",IFERROR(SUMIFS(Base!$P$3:$P$980,Base!$I$3:$I$980,$B35)/SUMIFS(Base!$L$3:$L$980,Base!$I$3:$I$980,$B35),"")) -> 7.2381009
B36: =IFERROR(INDEX(Base!$I$3:$I$980,MATCH(SMALL(Base!$Q$3:$Q$980,7),Base!$Q$3:$Q$980,0)),"") -> POLENGHI2 | C36: =IF($B36="","",IFERROR(SUMIFS(Base!$P$3:$P$980,Base!$I$3:$I$980,$B36,Base!$J$3:$J$980,"Ara")/SUMIFS(Base!$L$3:$L$980,Base!$I$3:$I$980,$B36,Base!$J$3:$J$980,"Ara"),"")) -> 7.0835447 | D36: =IF($B36="","",IFERROR(SUMIFS(Base!$P$3:$P$980,Base!$I$3:$I$980,$B36,Base!$J$3:$J$980,"Jpe")/SUMIFS(Base!$L$3:$L$980,Base!$I$3:$I$980,$B36,Base!$J$3:$J$980,"Jpe"),"")) -> 13.360213 | E36: =IF($B36="","",IFERROR(SUMIFS(Base!$P$3:$P$980,Base!$I$3:$I$980,$B36)/SUMIFS(Base!$L$3:$L$980,Base!$I$3:$I$980,$B36),"")) -> 7.9816331
B37: =IFERROR(INDEX(Base!$I$3:$I$980,MATCH(SMALL(Base!$Q$3:$Q$980,8),Base!$Q$3:$Q$980,0)),"") -> POLENGHI | C37: =IF($B37="","",IFERROR(SUMIFS(Base!$P$3:$P$980,Base!$I$3:$I$980,$B37,Base!$J$3:$J$980,"Ara")/SUMIFS(Base!$L$3:$L$980,Base!$I$3:$I$980,$B37,Base!$J$3:$J$980,"Ara"),"")) -> 10.976975 | D37: =IF($B37="","",IFERROR(SUMIFS(Base!$P$3:$P$980,Base!$I$3:$I$980,$B37,Base!$J$3:$J$980,"Jpe")/SUMIFS(Base!$L$3:$L$980,Base!$I$3:$I$980,$B37,Base!$J$3:$J$980,"Jpe"),"")) -> 11.53701 | E37: =IF($B37="","",IFERROR(SUMIFS(Base!$P$3:$P$980,Base!$I$3:$I$980,$B37)/SUMIFS(Base!$L$3:$L$980,Base!$I$3:$I$980,$B37),"")) -> 11.209469
B38: =IFERROR(INDEX(Base!$I$3:$I$980,MATCH(SMALL(Base!$Q$3:$Q$980,9),Base!$Q$3:$Q$980,0)),"") -> LACTALIS1 | C38: =IF($B38="","",IFERROR(SUMIFS(Base!$P$3:$P$980,Base!$I$3:$I$980,$B38,Base!$J$3:$J$980,"Ara")/SUMIFS(Base!$L$3:$L$980,Base!$I$3:$I$980,$B38,Base!$J$3:$J$980,"Ara"),"")) -> 7.803627 | D38: =IF($B38="","",IFERROR(SUMIFS(Base!$P$3:$P$980,Base!$I$3:$I$980,$B38,Base!$J$3:$J$980,"Jpe")/SUMIFS(Base!$L$3:$L$980,Base!$I$3:$I$980,$B38,Base!$J$3:$J$980,"Jpe"),"")) -> 16.000371 | E38: =IF($B38="","",IFERROR(SUMIFS(Base!$P$3:$P$980,Base!$I$3:$I$980,$B38)/SUMIFS(Base!$L$3:$L$980,Base!$I$3:$I$980,$B38),"")) -> 11.905784
B39: =IFERROR(INDEX(Base!$I$3:$I$980,MATCH(SMALL(Base!$Q$3:$Q$980,10),Base!$Q$3:$Q$980,0)),"") -> INNOVAPACK | C39: =IF($B39="","",IFERROR(SUMIFS(Base!$P$3:$P$980,Base!$I$3:$I$980,$B39,Base!$J$3:$J$980,"Ara")/SUMIFS(Base!$L$3:$L$980,Base!$I$3:$I$980,$B39,Base!$J$3:$J$980,"Ara"),"")) -> 12.080257 | D39: =IF($B39="","",IFERROR(SUMIFS(Base!$P$3:$P$980,Base!$I$3:$I$980,$B39,Base!$J$3:$J$980,"Jpe")/SUMIFS(Base!$L$3:$L$980,Base!$I$3:$I$980,$B39,Base!$J$3:$J$980,"Jpe"),"")) -> 11.710674 | E39: =IF($B39="","",IFERROR(SUMIFS(Base!$P$3:$P$980,Base!$I$3:$I$980,$B39)/SUMIFS(Base!$L$3:$L$980,Base!$I$3:$I$980,$B39),"")) -> 11.936296
B40: =IFERROR(INDEX(Base!$I$3:$I$980,MATCH(SMALL(Base!$Q$3:$Q$980,11),Base!$Q$3:$Q$980,0)),"") -> BO PACK | C40: =IF($B40="","",IFERROR(SUMIFS(Base!$P$3:$P$980,Base!$I$3:$I$980,$B40,Base!$J$3:$J$980,"Ara")/SUMIFS(Base!$L$3:$L$980,Base!$I$3:$I$980,$B40,Base!$J$3:$J$980,"Ara"),"")) -> 16.083917 | D40: =IF($B40="","",IFERROR(SUMIFS(Base!$P$3:$P$980,Base!$I$3:$I$980,$B40,Base!$J$3:$J$980,"Jpe")/SUMIFS(Base!$L$3:$L$980,Base!$I$3:$I$980,$B40,Base!$J$3:$J$980,"Jpe"),"")) -> 9.1062614 | E40: =IF($B40="","",IFERROR(SUMIFS(Base!$P$3:$P$980,Base!$I$3:$I$980,$B40)/SUMIFS(Base!$L$3:$L$980,Base!$I$3:$I$980,$B40),"")) -> 12.515114
B41: =IFERROR(INDEX(Base!$I$3:$I$980,MATCH(SMALL(Base!$Q$3:$Q$980,12),Base!$Q$3:$Q$980,0)),"") -> ALIBEY | C41: =IF($B41="","",IFERROR(SUMIFS(Base!$P$3:$P$980,Base!$I$3:$I$980,$B41,Base!$J$3:$J$980,"Ara")/SUMIFS(Base!$L$3:$L$980,Base!$I$3:$I$980,$B41,Base!$J$3:$J$980,"Ara"),"")) -> 15.918132 | D41: =IF($B41="","",IFERROR(SUMIFS(Base!$P$3:$P$980,Base!$I$3:$I$980,$B41,Base!$J$3:$J$980,"Jpe")/SUMIFS(Base!$L$3:$L$980,Base!$I$3:$I$980,$B41,Base!$J$3:$J$980,"Jpe"),"")) -> 7.6015588 | E41: =IF($B41="","",IFERROR(SUMIFS(Base!$P$3:$P$980,Base!$I$3:$I$980,$B41)/SUMIFS(Base!$L$3:$L$980,Base!$I$3:$I$980,$B41),"")) -> 12.659692
B42: =IFERROR(INDEX(Base!$I$3:$I$980,MATCH(SMALL(Base!$Q$3:$Q$980,13),Base!$Q$3:$Q$980,0)),"") -> C. CLARO | C42: =IF($B42="","",IFERROR(SUMIFS(Base!$P$3:$P$980,Base!$I$3:$I$980,$B42,Base!$J$3:$J$980,"Ara")/SUMIFS(Base!$L$3:$L$980,Base!$I$3:$I$980,$B42,Base!$J$3:$J$980,"Ara"),"")) -> 14.897463 | D42: =IF($B42="","",IFERROR(SUMIFS(Base!$P$3:$P$980,Base!$I$3:$I$980,$B42,Base!$J$3:$J$980,"Jpe")/SUMIFS(Base!$L$3:$L$980,Base!$I$3:$I$980,$B42,Base!$J$3:$J$980,"Jpe"),"")) -> 10.199849 | E42: =IF($B42="","",IFERROR(SUMIFS(Base!$P$3:$P$980,Base!$I$3:$I$980,$B42)/SUMIFS(Base!$L$3:$L$980,Base!$I$3:$I$980,$B42),"")) -> 13.164519
B43: =IFERROR(INDEX(Base!$I$3:$I$980,MATCH(SMALL(Base!$Q$3:$Q$980,14),Base!$Q$3:$Q$980,0)),"") -> TRENIER | C43: =IF($B43="","",IFERROR(SUMIFS(Base!$P$3:$P$980,Base!$I$3:$I$980,$B43,Base!$J$3:$J$980,"Ara")/SUMIFS(Base!$L$3:$L$980,Base!$I$3:$I$980,$B43,Base!$J$3:$J$980,"Ara"),"")) -> 13.661615 | D43: =IF($B43="","",IFERROR(SUMIFS(Base!$P$3:$P$980,Base!$I$3:$I$980,$B43,Base!$J$3:$J$980,"Jpe")/SUMIFS(Base!$L$3:$L$980,Base!$I$3:$I$980,$B43,Base!$J$3:$J$980,"Jpe"),"")) -> 12.594968 | E43: =IF($B43="","",IFERROR(SUMIFS(Base!$P$3:$P$980,Base!$I$3:$I$980,$B43)/SUMIFS(Base!$L$3:$L$980,Base!$I$3:$I$980,$B43),"")) -> 13.368383
B44: =IFERROR(INDEX(Base!$I$3:$I$980,MATCH(SMALL(Base!$Q$3:$Q$980,15),Base!$Q$3:$Q$980,0)),"") -> FERRERO BR | C44: =IF($B44="","",IFERROR(SUMIFS(Base!$P$3:$P$980,Base!$I$3:$I$980,$B44,Base!$J$3:$J$980,"Ara")/SUMIFS(Base!$L$3:$L$980,Base!$I$3:$I$980,$B44,Base!$J$3:$J$980,"Ara"),"")) -> 11.673692 | D44: =IF($B44="","",IFERROR(SUMIFS(Base!$P$3:$P$980,Base!$I$3:$I$980,$B44,Base!$J$3:$J$980,"Jpe")/SUMIFS(Base!$L$3:$L$980,Base!$I$3:$I$980,$B44,Base!$J$3:$J$980,"Jpe"),"")) -> 16 | E44: =IF($B44="","",IFERROR(SUMIFS(Base!$P$3:$P$980,Base!$I$3:$I$980,$B44)/SUMIFS(Base!$L$3:$L$980,Base!$I$3:$I$980,$B44),"")) -> 13.473545
B45: =IFERROR(INDEX(Base!$I$3:$I$980,MATCH(SMALL(Base!$Q$3:$Q$980,16),Base!$Q$3:$Q$980,0)),"") -> POLENGHI I | C45: =IF($B45="","",IFERROR(SUMIFS(Base!$P$3:$P$980,Base!$I$3:$I$980,$B45,Base!$J$3:$J$980,"Ara")/SUMIFS(Base!$L$3:$L$980,Base!$I$3:$I$980,$B45,Base!$J$3:$J$980,"Ara"),"")) -> 14.314894 | D45: =IF($B45="","",IFERROR(SUMIFS(Base!$P$3:$P$980,Base!$I$3:$I$980,$B45,Base!$J$3:$J$980,"Jpe")/SUMIFS(Base!$L$3:$L$980,Base!$I$3:$I$980,$B45,Base!$J$3:$J$980,"Jpe"),"")) -> 12.015395 | E45: =IF($B45="","",IFERROR(SUMIFS(Base!$P$3:$P$980,Base!$I$3:$I$980,$B45)/SUMIFS(Base!$L$3:$L$980,Base!$I$3:$I$980,$B45),"")) -> 13.531243
B46: =IFERROR(INDEX(Base!$I$3:$I$980,MATCH(SMALL(Base!$Q$3:$Q$980,17),Base!$Q$3:$Q$980,0)),"") -> KERRY4 | C46: =IF($B46="","",IFERROR(SUMIFS(Base!$P$3:$P$980,Base!$I$3:$I$980,$B46,Base!$J$3:$J$980,"Ara")/SUMIFS(Base!$L$3:$L$980,Base!$I$3:$I$980,$B46,Base!$J$3:$J$980,"Ara"),"")) -> 15 | D46: =IF($B46="","",IFERROR(SUMIFS(Base!$P$3:$P$980,Base!$I$3:$I$980,$B46,Base!$J$3:$J$980,"Jpe")/SUMIFS(Base!$L$3:$L$980,Base!$I$3:$I$980,$B46,Base!$J$3:$J$980,"Jpe"),"")) -> 0 | E46: =IF($B46="","",IFERROR(SUMIFS(Base!$P$3:$P$980,Base!$I$3:$I$980,$B46)/SUMIFS(Base!$L$3:$L$980,Base!$I$3:$I$980,$B46),"")) -> 13.567886
B47: =IFERROR(INDEX(Base!$I$3:$I$980,MATCH(SMALL(Base!$Q$3:$Q$980,18),Base!$Q$3:$Q$980,0)),"") -> PLANTPLUS2 | C47: =IF($B47="","",IFERROR(SUMIFS(Base!$P$3:$P$980,Base!$I$3:$I$980,$B47,Base!$J$3:$J$980,"Ara")/SUMIFS(Base!$L$3:$L$980,Base!$I$3:$I$980,$B47,Base!$J$3:$J$980,"Ara"),"")) -> 13.630013 | D47: =IF($B47="","",IFERROR(SUMIFS(Base!$P$3:$P$980,Base!$I$3:$I$980,$B47,Base!$J$3:$J$980,"Jpe")/SUMIFS(Base!$L$3:$L$980,Base!$I$3:$I$980,$B47,Base!$J$3:$J$980,"Jpe"),"")) -> 16 | E47: =IF($B47="","",IFERROR(SUMIFS(Base!$P$3:$P$980,Base!$I$3:$I$980,$B47)/SUMIFS(Base!$L$3:$L$980,Base!$I$3:$I$980,$B47),"")) -> 14.182656
...

Sheet Ara
B2: DOH Araucária – por Categoria
B5: Categoria / Item | C5: Fornecedor | D5: SAP | E5: Estoque (cx) | F5: Demanda (cx/dia) | G5: DOH | H5: PE | I5: DOH Considerado | J5: Ranking categoria (1 = mais crítica) | K5: Chave
B6: BEBIDAS | E6: =SUMIFS(Base!$K$3:$K$980,Base!$J$3:$J$980,"Ara",Base!$G$3:$G$980,$B6,Base!$K$3:$K$980,"<>#N/A") -> 25334 | F6: =SUMIFS(Base!$L$3:$L$980,Base!$J$3:$J$980,"Ara",Base!$G$3:$G$980,$B6) -> 470.41803 | G6: =IFERROR(E6/F6,0) -> 53.854229 | I6: =IFERROR(SUMIFS(Base!$P$3:$P$980,Base!$J$3:$J$980,"Ara",Base!$G$3:$G$980,$B6)/F6,0) -> 19.542407 | J6: =1+SUMPRODUCT(($K$6:$K$114="")*($I$6:$I$114<I6)) -> 9
B7: =INDEX(Base!$H$3:$H$980,MATCH($K7,Base!$B$3:$B$980,0)) -> SUCO UVA/ MACA NATURAL ONE 180 ML FD C/6UN | C7: =IFERROR(IF(INDEX(Base!$I$3:$I$980,MATCH($K7,Base!$B$3:$B$980,0))="","",INDEX(Base!$I$3:$I$980,MATCH($K7,Base!$B$3:$B$980,0))),"sem fornecedor") -> NATURALONE | D7: =INDEX(Base!$E$3:$E$980,MATCH($K7,Base!$B$3:$B$980,0)) -> 221000000780 | E7: =IFERROR(INDEX(Base!$K$3:$K$980,MATCH($K7,Base!$B$3:$B$980,0)),"sem estoque") -> 13735 | F7: =INDEX(Base!$L$3:$L$980,MATCH($K7,Base!$B$3:$B$980,0)) -> 209.40989 | G7: =INDEX(Base!$M$3:$M$980,MATCH($K7,Base!$B$3:$B$980,0)) -> 65.58907 | H7: =INDEX(Base!$N$3:$N$980,MATCH($K7,Base!$B$3:$B$980,0)) -> 20.83083 | I7: =INDEX(Base!$O$3:$O$980,MATCH($K7,Base!$B$3:$B$980,0)) -> 20.83083 | K7: 221000000780Ara
B8: =INDEX(Base!$H$3:$H$980,MATCH($K8,Base!$B$3:$B$980,0)) -> SUCO LARANJA COM MACA FD 12X300ML | C8: =IFERROR(IF(INDEX(Base!$I$3:$I$980,MATCH($K8,Base!$B$3:$B$980,0))="","",INDEX(Base!$I$3:$I$980,MATCH($K8,Base!$B$3:$B$980,0))),"sem fornecedor") -> NATURALONE | D8: =INDEX(Base!$E$3:$E$980,MATCH($K8,Base!$B$3:$B$980,0)) -> 221000000541 | E8: =IFERROR(INDEX(Base!$K$3:$K$980,MATCH($K8,Base!$B$3:$B$980,0)),"sem estoque") -> 3946 | F8: =INDEX(Base!$L$3:$L$980,MATCH($K8,Base!$B$3:$B$980,0)) -> 115.85308 | G8: =INDEX(Base!$M$3:$M$980,MATCH($K8,Base!$B$3:$B$980,0)) -> 34.06038 | H8: =INDEX(Base!$N$3:$N$980,MATCH($K8,Base!$B$3:$B$980,0)) -> 15 | I8: =INDEX(Base!$O$3:$O$980,MATCH($K8,Base!$B$3:$B$980,0)) -> 15 | K8: 221000000541Ara
B9: =INDEX(Base!$H$3:$H$980,MATCH($K9,Base!$B$3:$B$980,0)) -> SUCO UVA MACA 12X300ML PPY/BK | C9: =IFERROR(IF(INDEX(Base!$I$3:$I$980,MATCH($K9,Base!$B$3:$B$980,0))="","",INDEX(Base!$I$3:$I$980,MATCH($K9,Base!$B$3:$B$980,0))),"sem fornecedor") -> NATURALONE | D9: =INDEX(Base!$E$3:$E$980,MATCH($K9,Base!$B$3:$B$980,0)) -> 201080000086 | E9: =IFERROR(INDEX(Base!$K$3:$K$980,MATCH($K9,Base!$B$3:$B$980,0)),"sem estoque") -> 7159 | F9: =INDEX(Base!$L$3:$L$980,MATCH($K9,Base!$B$3:$B$980,0)) -> 124.85038 | G9: =INDEX(Base!$M$3:$M$980,MATCH($K9,Base!$B$3:$B$980,0)) -> 57.340632 | H9: =INDEX(Base!$N$3:$N$980,MATCH($K9,Base!$B$3:$B$980,0)) -> 20.817897 | I9: =INDEX(Base!$O$3:$O$980,MATCH($K9,Base!$B$3:$B$980,0)) -> 20.817897 | K9: 201080000086Ara
B10: =INDEX(Base!$H$3:$H$980,MATCH($K10,Base!$B$3:$B$980,0)) -> AGUA MINERAL BURGER KING CX 48 UN | C10: =IFERROR(IF(INDEX(Base!$I$3:$I$980,MATCH($K10,Base!$B$3:$B$980,0))="","",INDEX(Base!$I$3:$I$980,MATCH($K10,Base!$B$3:$B$980,0))),"sem fornecedor") -> FLAMIN | D10: =INDEX(Base!$E$3:$E$980,MATCH($K10,Base!$B$3:$B$980,0)) -> 201080000005 | E10: =IFERROR(INDEX(Base!$K$3:$K$980,MATCH($K10,Base!$B$3:$B$980,0)),"sem estoque") -> 494 | F10: =INDEX(Base!$L$3:$L$980,MATCH($K10,Base!$B$3:$B$980,0)) -> 20.30467 | G10: =INDEX(Base!$M$3:$M$980,MATCH($K10,Base!$B$3:$B$980,0)) -> 24.329379 | H10: =INDEX(Base!$N$3:$N$980,MATCH($K10,Base!$B$3:$B$980,0)) -> 31 | I10: =INDEX(Base!$O$3:$O$980,MATCH($K10,Base!$B$3:$B$980,0)) -> 24.329379 | K10: 201080000005Ara
B11: PÃES | E11: =SUMIFS(Base!$K$3:$K$980,Base!$J$3:$J$980,"Ara",Base!$G$3:$G$980,$B11,Base!$K$3:$K$980,"<>#N/A") -> 8281 | F11: =SUMIFS(Base!$L$3:$L$980,Base!$J$3:$J$980,"Ara",Base!$G$3:$G$980,$B11) -> 618.17641 | G11: =IFERROR(E11/F11,0) -> 13.395853 | I11: =IFERROR(SUMIFS(Base!$P$3:$P$980,Base!$J$3:$J$980,"Ara",Base!$G$3:$G$980,$B11)/F11,0) -> 7.8057792 | J11: =1+SUMPRODUCT(($K$6:$K$114="")*($I$6:$I$114<I11)) -> 1
B12: =INDEX(Base!$H$3:$H$980,MATCH($K12,Base!$B$3:$B$980,0)) -> PAO BK 5 CL CXG CONG 10500G UNB | C12: =IFERROR(IF(INDEX(Base!$I$3:$I$980,MATCH($K12,Base!$B$3:$B$980,0))="","",INDEX(Base!$I$3:$I$980,MATCH($K12,Base!$B$3:$B$980,0))),"sem fornecedor") -> BIMBO | D12: =INDEX(Base!$E$3:$E$980,MATCH($K12,Base!$B$3:$B$980,0)) -> 201010000575 | E12: =IFERROR(INDEX(Base!$K$3:$K$980,MATCH($K12,Base!$B$3:$B$980,0)),"sem estoque") -> 3646 | F12: =INDEX(Base!$L$3:$L$980,MATCH($K12,Base!$B$3:$B$980,0)) -> 293.73136 | G12: =INDEX(Base!$M$3:$M$980,MATCH($K12,Base!$B$3:$B$980,0)) -> 12.412703 | H12: =INDEX(Base!$N$3:$N$980,MATCH($K12,Base!$B$3:$B$980,0)) -> 7.03 | I12: =INDEX(Base!$O$3:$O$980,MATCH($K12,Base!$B$3:$B$980,0)) -> 7.03 | K12: 201010000575Ara
B13: =INDEX(Base!$H$3:$H$980,MATCH($K13,Base!$B$3:$B$980,0)) -> PAO BK 4 CONG CXG 14900G UNB | C13: =IFERROR(IF(INDEX(Base!$I$3:$I$980,MATCH($K13,Base!$B$3:$B$980,0))="","",INDEX(Base!$I$3:$I$980,MATCH($K13,Base!$B$3:$B$980,0))),"sem fornecedor") -> BIMBO | D13: =INDEX(Base!$E$3:$E$980,MATCH($K13,Base!$B$3:$B$980,0)) -> 201010000262 | E13: =IFERROR(INDEX(Base!$K$3:$K$980,MATCH($K13,Base!$B$3:$B$980,0)),"sem estoque") -> 3448 | F13: =INDEX(Base!$L$3:$L$980,MATCH($K13,Base!$B$3:$B$980,0)) -> 272.30958 | G13: =INDEX(Base!$M$3:$M$980,MATCH($K13,Base!$B$3:$B$980,0)) -> 12.662059 | H13: =INDEX(Base!$N$3:$N$980,MATCH($K13,Base!$B$3:$B$980,0)) -> 7.86 | I13: =INDEX(Base!$O$3:$O$980,MATCH($K13,Base!$B$3:$B$980,0)) -> 7.86 | K13: 201010000262Ara
B14: =INDEX(Base!$H$3:$H$980,MATCH($K14,Base!$B$3:$B$980,0)) -> PAO SUPREMO BK CONG CX 180 UND | C14: =IFERROR(IF(INDEX(Base!$I$3:$I$980,MATCH($K14,Base!$B$3:$B$980,0))="","",INDEX(Base!$I$3:$I$980,MATCH($K14,Base!$B$3:$B$980,0))),"sem fornecedor") -> BIMBO | D14: =INDEX(Base!$E$3:$E$980,MATCH($K14,Base!$B$3:$B$980,0)) -> 201010000368 | E14: =IFERROR(INDEX(Base!$K$3:$K$980,MATCH($K14,Base!$B$3:$B$980,0)),"sem estoque") -> 760 | F14: =INDEX(Base!$L$3:$L$980,MATCH($K14,Base!$B$3:$B$980,0)) -> 32.393656 | G14: =INDEX(Base!$M$3:$M$980,MATCH($K14,Base!$B$3:$B$980,0)) -> 23.461384 | H14: =INDEX(Base!$N$3:$N$980,MATCH($K14,Base!$B$3:$B$980,0)) -> 10 | I14: =INDEX(Base!$O$3:$O$980,MATCH($K14,Base!$B$3:$B$980,0)) -> 10 | K14: 201010000368Ara
B15: =INDEX(Base!$H$3:$H$980,MATCH($K15,Base!$B$3:$B$980,0)) -> PAO BRIOCHE BK CX 192 UND | C15: =IFERROR(IF(INDEX(Base!$I$3:$I$980,MATCH($K15,Base!$B$3:$B$980,0))="","",INDEX(Base!$I$3:$I$980,MATCH($K15,Base!$B$3:$B$980,0))),"sem fornecedor") -> BIMBO | D15: =INDEX(Base!$E$3:$E$980,MATCH($K15,Base!$B$3:$B$980,0)) -> 201010000492 | E15: =IFERROR(INDEX(Base!$K$3:$K$980,MATCH($K15,Base!$B$3:$B$980,0)),"sem estoque") -> 427 | F15: =INDEX(Base!$L$3:$L$980,MATCH($K15,Base!$B$3:$B$980,0)) -> 19.741816 | G15: =INDEX(Base!$M$3:$M$980,MATCH($K15,Base!$B$3:$B$980,0)) -> 21.629216 | H15: =INDEX(Base!$N$3:$N$980,MATCH($K15,Base!$B$3:$B$980,0)) -> 15 | I15: =INDEX(Base!$O$3:$O$980,MATCH($K15,Base!$B$3:$B$980,0)) -> 15 | K15: 201010000492Ara
B16: PROTEINAS | E16: =SUMIFS(Base!$K$3:$K$980,Base!$J$3:$J$980,"Ara",Base!$G$3:$G$980,$B16,Base!$K$3:$K$980,"<>#N/A") -> 17844 | F16: =SUMIFS(Base!$L$3:$L$980,Base!$J$3:$J$980,"Ara",Base!$G$3:$G$980,$B16) -> 938.51104 | G16: =IFERROR(E16/F16,0) -> 19.013096 | I16: =IFERROR(SUMIFS(Base!$P$3:$P$980,Base!$J$3:$J$980,"Ara",Base!$G$3:$G$980,$B16)/F16,0) -> 9.9739293 | J16: =1+SUMPRODUCT(($K$6:$K$114="")*($I$6:$I$114<I16)) -> 3
B17: =INDEX(Base!$H$3:$H$980,MATCH($K17,Base!$B$3:$B$980,0)) -> CHICKEN JR CLEAN BK CX 9,88KG | C17: =IFERROR(IF(INDEX(Base!$I$3:$I$980,MATCH($K17,Base!$B$3:$B$980,0))="","",INDEX(Base!$I$3:$I$980,MATCH($K17,Base!$B$3:$B$980,0))),"sem fornecedor") -> SEARA | D17: =INDEX(Base!$E$3:$E$980,MATCH($K17,Base!$B$3:$B$980,0)) -> 201010000218 | E17: =IFERROR(INDEX(Base!$K$3:$K$980,MATCH($K17,Base!$B$3:$B$980,0)),"sem estoque") -> 3948 | F17: =INDEX(Base!$L$3:$L$980,MATCH($K17,Base!$B$3:$B$980,0)) -> 161.22673 | G17: =INDEX(Base!$M$3:$M$980,MATCH($K17,Base!$B$3:$B$980,0)) -> 24.487255 | H17: =INDEX(Base!$N$3:$N$980,MATCH($K17,Base!$B$3:$B$980,0)) -> 14.268349 | I17: =INDEX(Base!$O$3:$O$980,MATCH($K17,Base!$B$3:$B$980,0)) -> 14.268349 | K17: 201010000218Ara
B18: =INDEX(Base!$H$3:$H$980,MATCH($K18,Base!$B$3:$B$980,0)) -> CARNE CONG MOIDA WHOPPER BK CX 17,2KG | C18: =IFERROR(IF(INDEX(Base!$I$3:$I$980,MATCH($K18,Base!$B$3:$B$980,0))="","",INDEX(Base!$I$3:$I$980,MATCH($K18,Base!$B$3:$B$980,0))),"sem fornecedor") -> JBS | D18: =INDEX(Base!$E$3:$E$980,MATCH($K18,Base!$B$3:$B$980,0)) -> 201010000209 | E18: =IFERROR(INDEX(Base!$K$3:$K$980,MATCH($K18,Base!$B$3:$B$980,0)),"sem estoque") -> 5121 | F18: =INDEX(Base!$L$3:$L$980,MATCH($K18,Base!$B$3:$B$980,0)) -> 315.94685 | G18: =INDEX(Base!$M$3:$M$980,MATCH($K18,Base!$B$3:$B$980,0)) -> 16.208422 | H18: =INDEX(Base!$N$3:$N$980,MATCH($K18,Base!$B$3:$B$980,0)) -> 7 | I18: =INDEX(Base!$O$3:$O$980,MATCH($K18,Base!$B$3:$B$980,0)) -> 7 | K18: 201010000209Ara
B19: =INDEX(Base!$H$3:$H$980,MATCH($K19,Base!$B$3:$B$980,0)) -> CARNE HB CONG BKC CX COM 18,7 KG | C19: =IFERROR(IF(INDEX(Base!$I$3:$I$980,MATCH($K19,Base!$B$3:$B$980,0))="","",INDEX(Base!$I$3:$I$980,MATCH($K19,Base!$B$3:$B$980,0))),"sem fornecedor") -> JBS | D19: =INDEX(Base!$E$3:$E$980,MATCH($K19,Base!$B$3:$B$980,0)) -> 201010000645 | E19: =IFERROR(INDEX(Base!$K$3:$K$980,MATCH($K19,Base!$B$3:$B$980,0)),"sem estoque") -> 5060 | F19: =INDEX(Base!$L$3:$L$980,MATCH($K19,Base!$B$3:$B$980,0)) -> 264.3624 | G19: =INDEX(Base!$M$3:$M$980,MATCH($K19,Base!$B$3:$B$980,0)) -> 19.140392 | H19: =INDEX(Base!$N$3:$N$980,MATCH($K19,Base!$B$3:$B$980,0)) -> 7 | I19: =INDEX(Base!$O$3:$O$980,MATCH($K19,Base!$B$3:$B$980,0)) -> 7 | K19: 201010000645Ara
B20: =INDEX(Base!$H$3:$H$980,MATCH($K20,Base!$B$3:$B$980,0)) -> CHICKEN NUGGETS CX COM 12 KG | C20: =IFERROR(IF(INDEX(Base!$I$3:$I$980,MATCH($K20,Base!$B$3:$B$980,0))="","",INDEX(Base!$I$3:$I$980,MATCH($K20,Base!$B$3:$B$980,0))),"sem fornecedor") -> SEARA | D20: =INDEX(Base!$E$3:$E$980,MATCH($K20,Base!$B$3:$B$980,0)) -> 201010000565 | E20: =IFERROR(INDEX(Base!$K$3:$K$980,MATCH($K20,Base!$B$3:$B$980,0)),"sem estoque") -> 1307 | F20: =INDEX(Base!$L$3:$L$980,MATCH($K20,Base!$B$3:$B$980,0)) -> 88.97976 | G20: =INDEX(Base!$M$3:$M$980,MATCH($K20,Base!$B$3:$B$980,0)) -> 14.688734 | H20: =INDEX(Base!$N$3:$N$980,MATCH($K20,Base!$B$3:$B$980,0)) -> 19.443119 | I20: =INDEX(Base!$O$3:$O$980,MATCH($K20,Base!$B$3:$B$980,0)) -> 14.688734 | K20: 201010000565Ara
B21: =INDEX(Base!$H$3:$H$980,MATCH($K21,Base!$B$3:$B$980,0)) -> BACON PRONTO CONG 1187 UND CX 4KG DIS | C21: =IFERROR(IF(INDEX(Base!$I$3:$I$980,MATCH($K21,Base!$B$3:$B$980,0))="","",INDEX(Base!$I$3:$I$980,MATCH($K21,Base!$B$3:$B$980,0))),"sem fornecedor") -> SEARA2 | D21: =INDEX(Base!$E$3:$E$980,MATCH($K21,Base!$B$3:$B$980,0)) -> 201010000684 | E21: =IFERROR(INDEX(Base!$K$3:$K$980,MATCH($K21,Base!$B$3:$B$980,0)),"sem estoque") -> 1076 | F21: =INDEX(Base!$L$3:$L$980,MATCH($K21,Base!$B$3:$B$980,0)) -> 70.1693 | G21: =INDEX(Base!$M$3:$M$980,MATCH($K21,Base!$B$3:$B$980,0)) -> 15.334341 | H21: =INDEX(Base!$N$3:$N$980,MATCH($K21,Base!$B$3:$B$980,0)) -> 17.149905 | I21: =INDEX(Base!$O$3:$O$980,MATCH($K21,Base!$B$3:$B$980,0)) -> 15.334341 | K21: 201010000684Ara
B22: =INDEX(Base!$H$3:$H$980,MATCH($K22,Base!$B$3:$B$980,0)) -> BACON BK ASS CUBOS CX 2X1KG | C22: =IFERROR(IF(INDEX(Base!$I$3:$I$980,MATCH($K22,Base!$B$3:$B$980,0))="","",INDEX(Base!$I$3:$I$980,MATCH($K22,Base!$B$3:$B$980,0))),"sem fornecedor") -> MINERVA | D22: =INDEX(Base!$E$3:$E$980,MATCH($K22,Base!$B$3:$B$980,0)) -> 201010000402 | E22: =IFERROR(INDEX(Base!$K$3:$K$980,MATCH($K22,Base!$B$3:$B$980,0)),"sem estoque") -> 451 | F22: =INDEX(Base!$L$3:$L$980,MATCH($K22,Base!$B$3:$B$980,0)) -> 17.503592 | G22: =INDEX(Base!$M$3:$M$980,MATCH($K22,Base!$B$3:$B$980,0)) -> 25.76614 | H22: =INDEX(Base!$N$3:$N$980,MATCH($K22,Base!$B$3:$B$980,0)) -> 16.148955 | I22: =INDEX(Base!$O$3:$O$980,MATCH($K22,Base!$B$3:$B$980,0)) -> 16.148955 | K22: 201010000402Ara
B23: =INDEX(Base!$H$3:$H$980,MATCH($K23,Base!$B$3:$B$980,0)) -> TENDER CRISPY FILE NOVO BK CX 4X2,5 KG | C23: =IFERROR(IF(INDEX(Base!$I$3:$I$980,MATCH($K23,Base!$B$3:$B$980,0))="","",INDEX(Base!$I$3:$I$980,MATCH($K23,Base!$B$3:$B$980,0))),"sem fornecedor") -> BRF | D23: =INDEX(Base!$E$3:$E$980,MATCH($K23,Base!$B$3:$B$980,0)) -> 201010000539 | E23: =IFERROR(INDEX(Base!$K$3:$K$980,MATCH($K23,Base!$B$3:$B$980,0)),"sem estoque") -> 759 | F23: =INDEX(Base!$L$3:$L$980,MATCH($K23,Base!$B$3:$B$980,0)) -> 11.371565 | G23: =INDEX(Base!$M$3:$M$980,MATCH($K23,Base!$B$3:$B$980,0)) -> 66.745432 | H23: =INDEX(Base!$N$3:$N$980,MATCH($K23,Base!$B$3:$B$980,0)) -> 18.5 | I23: =INDEX(Base!$O$3:$O$980,MATCH($K23,Base!$B$3:$B$980,0)) -> 18.5 | K23: 201010000539Ara
B24: =INDEX(Base!$H$3:$H$980,MATCH($K24,Base!$B$3:$B$980,0)) -> HAMBURGUER REBEL SABOR PICANHA CX 122 UND 12KG | C24: =IFERROR(IF(INDEX(Base!$I$3:$I$980,MATCH($K24,Base!$B$3:$B$980,0))="","",INDEX(Base!$I$3:$I$980,MATCH($K24,Base!$B$3:$B$980,0))),"sem fornecedor") -> PLANTPLUS2 | D24: =INDEX(Base!$E$3:$E$980,MATCH($K24,Base!$B$3:$B$980,0)) -> 201010000654 | E24: =IFERROR(INDEX(Base!$K$3:$K$980,MATCH($K24,Base!$B$3:$B$980,0)),"sem estoque") -> 122 | F24: =INDEX(Base!$L$3:$L$980,MATCH($K24,Base!$B$3:$B$980,0)) -> 8.9508349 | G24: =INDEX(Base!$M$3:$M$980,MATCH($K24,Base!$B$3:$B$980,0)) -> 13.630013 | H24: =INDEX(Base!$N$3:$N$980,MATCH($K24,Base!$B$3:$B$980,0)) -> 17.141751 | I24: =INDEX(Base!$O$3:$O$980,MATCH($K24,Base!$B$3:$B$980,0)) -> 13.630013 | K24: 201010000654Ara
B25: LÁCTEOS | E25: =SUMIFS(Base!$K$3:$K$980,Base!$J$3:$J$980,"Ara",Base!$G$3:$G$980,$B25,Base!$K$3:$K$980,"<>#N/A") -> 3466 | F25: =SUMIFS(Base!$L$3:$L$980,Base!$J$3:$J$980,"Ara",Base!$G$3:$G$980,$B25) -> 357.5008 | G25: =IFERROR(E25/F25,0) -> 9.6950832 | I25: =IFERROR(SUMIFS(Base!$P$3:$P$980,Base!$J$3:$J$980,"Ara",Base!$G$3:$G$980,$B25)/F25,0) -> 9.6950832 | J25: =1+SUMPRODUCT(($K$6:$K$114="")*($I$6:$I$114<I25)) -> 2
B26: =INDEX(Base!$H$3:$H$980,MATCH($K26,Base!$B$3:$B$980,0)) -> BEBIDA LACTEA UHT BAUNILHA BK 10 L X 2 UN | C26: =IFERROR(IF(INDEX(Base!$I$3:$I$980,MATCH($K26,Base!$B$3:$B$980,0))="","",INDEX(Base!$I$3:$I$980,MATCH($K26,Base!$B$3:$B$980,0))),"sem fornecedor") -> POLENGHI2 | D26: =INDEX(Base!$E$3:$E$980,MATCH($K26,Base!$B$3:$B$980,0)) -> 241000000044 | E26: =IFERROR(INDEX(Base!$K$3:$K$980,MATCH($K26,Base!$B$3:$B$980,0)),"sem estoque") -> 1329 | F26: =INDEX(Base!$L$3:$L$980,MATCH($K26,Base!$B$3:$B$980,0)) -> 187.14126 | G26: =INDEX(Base!$M$3:$M$980,MATCH($K26,Base!$B$3:$B$980,0)) -> 7.1015874 | H26: =INDEX(Base!$N$3:$N$980,MATCH($K26,Base!$B$3:$B$980,0)) -> 16.5 | I26: =INDEX(Base!$O$3:$O$980,MATCH($K26,Base!$B$3:$B$980,0)) -> 7.1015874 | K26: 241000000044Ara
B27: =INDEX(Base!$H$3:$H$980,MATCH($K27,Base!$B$3:$B$980,0)) -> QUEIJO CHEDDAR CLEAN NAC BK CX 17,66 KG | C27: =IFERROR(IF(INDEX(Base!$I$3:$I$980,MATCH($K27,Base!$B$3:$B$980,0))="","",INDEX(Base!$I$3:$I$980,MATCH($K27,Base!$B$3:$B$980,0))),"sem fornecedor") -> POLENGHI I | D27: =INDEX(Base!$E$3:$E$980,MATCH($K27,Base!$B$3:$B$980,0)) -> 201010000628 | E27: =IFERROR(INDEX(Base!$K$3:$K$980,MATCH($K27,Base!$B$3:$B$980,0)),"sem estoque") -> 1627 | F27: =INDEX(Base!$L$3:$L$980,MATCH($K27,Base!$B$3:$B$980,0)) -> 113.65785 | G27: =INDEX(Base!$M$3:$M$980,MATCH($K27,Base!$B$3:$B$980,0)) -> 14.314894 | H27: =INDEX(Base!$N$3:$N$980,MATCH($K27,Base!$B$3:$B$980,0)) -> 16.909982 | I27: =INDEX(Base!$O$3:$O$980,MATCH($K27,Base!$B$3:$B$980,0)) -> 14.314894 | K27: 201010000628Ara
B28: =INDEX(Base!$H$3:$H$980,MATCH($K28,Base!$B$3:$B$980,0)) -> BEBIDA LACTEA DOCE DE LEITE UHT BK CX10X2UN | C28: =IFERROR(IF(INDEX(Base!$I$3:$I$980,MATCH($K28,Base!$B$3:$B$980,0))="","",INDEX(Base!$I$3:$I$980,MATCH($K28,Base!$B$3:$B$980,0))),"sem fornecedor") -> POLENGHI2 | D28: =INDEX(Base!$E$3:$E$980,MATCH($K28,Base!$B$3:$B$980,0)) -> 201010000527 | E28: =IFERROR(INDEX(Base!$K$3:$K$980,MATCH($K28,Base!$B$3:$B$980,0)),"sem estoque") -> 195 | F28: =INDEX(Base!$L$3:$L$980,MATCH($K28,Base!$B$3:$B$980,0)) -> 28.005264 | G28: =INDEX(Base!$M$3:$M$980,MATCH($K28,Base!$B$3:$B$980,0)) -> 6.9629767 | H28: =INDEX(Base!$N$3:$N$980,MATCH($K28,Base!$B$3:$B$980,0)) -> 18.887309 | I28: =INDEX(Base!$O$3:$O$980,MATCH($K28,Base!$B$3:$B$980,0)) -> 6.9629767 | K28: 201010000527Ara
B29: =INDEX(Base!$H$3:$H$980,MATCH($K29,Base!$B$3:$B$980,0)) -> MOLHO CHEDDAR BNG 2KGX8UN | C29: =IFERROR(IF(INDEX(Base!$I$3:$I$980,MATCH($K29,Base!$B$3:$B$980,0))="","",INDEX(Base!$I$3:$I$980,MATCH($K29,Base!$B$3:$B$980,0))),"sem fornecedor") -> POLENGHI | D29: =INDEX(Base!$E$3:$E$980,MATCH($K29,Base!$B$3:$B$980,0)) -> 201010006004 | E29: =IFERROR(INDEX(Base!$K$3:$K$980,MATCH($K29,Base!$B$3:$B$980,0)),"sem estoque") -> 315 | F29: =INDEX(Base!$L$3:$L$980,MATCH($K29,Base!$B$3:$B$980,0)) -> 28.696431 | G29: =INDEX(Base!$M$3:$M$980,MATCH($K29,Base!$B$3:$B$980,0)) -> 10.976975 | H29: =INDEX(Base!$N$3:$N$980,MATCH($K29,Base!$B$3:$B$980,0)) -> 19.862476 | I29: =INDEX(Base!$O$3:$O$980,MATCH($K29,Base!$B$3:$B$980,0)) -> 10.976975 | K29: 201010006004Ara
B30: MOLHOS | E30: =SUMIFS(Base!$K$3:$K$980,Base!$J$3:$J$980,"Ara",Base!$G$3:$G$980,$B30,Base!$K$3:$K$980,"<>#N/A") -> 8861 | F30: =SUMIFS(Base!$L$3:$L$980,Base!$J$3:$J$980,"Ara",Base!$G$3:$G$980,$B30) -> 337.75595 | G30: =IFERROR(E30/F30,0) -> 26.234919 | I30: =IFERROR(SUMIFS(Base!$P$3:$P$980,Base!$J$3:$J$980,"Ara",Base!$G$3:$G$980,$B30)/F30,0) -> 19.063392 | J30: =1+SUMPRODUCT(($K$6:$K$114="")*($I$6:$I$114<I30)) -> 8
B31: =INDEX(Base!$H$3:$H$980,MATCH($K31,Base!$B$3:$B$980,0)) -> MAIONESE BAG CX6X3KG | C31: =IFERROR(IF(INDEX(Base!$I$3:$I$980,MATCH($K31,Base!$B$3:$B$980,0))="","",INDEX(Base!$I$3:$I$980,MATCH($K31,Base!$B$3:$B$980,0))),"sem fornecedor") -> KERRY | D31: =INDEX(Base!$E$3:$E$980,MATCH($K31,Base!$B$3:$B$980,0)) -> 201010000317 | E31: =IFERROR(INDEX(Base!$K$3:$K$980,MATCH($K31,Base!$B$3:$B$980,0)),"sem estoque") -> 1242 | F31: =INDEX(Base!$L$3:$L$980,MATCH($K31,Base!$B$3:$B$980,0)) -> 73.593445 | G31: =INDEX(Base!$M$3:$M$980,MATCH($K31,Base!$B$3:$B$980,0)) -> 16.876503 | H31: =INDEX(Base!$N$3:$N$980,MATCH($K31,Base!$B$3:$B$980,0)) -> 15.966371 | I31: =INDEX(Base!$O$3:$O$980,MATCH($K31,Base!$B$3:$B$980,0)) -> 15.966371 | K31: 201010000317Ara
B32: =INDEX(Base!$H$3:$H$980,MATCH($K32,Base!$B$3:$B$980,0)) -> SACHE KETCHUP BK HEINZ CX 1500X7GR | C32: =IFERROR(IF(INDEX(Base!$I$3:$I$980,MATCH($K32,Base!$B$3:$B$980,0))="","",INDEX(Base!$I$3:$I$980,MATCH($K32,Base!$B$3:$B$980,0))),"sem fornecedor") -> HEINZ | D32: =INDEX(Base!$E$3:$E$980,MATCH($K32,Base!$B$3:$B$980,0)) -> 201010000417 | E32: =IFERROR(INDEX(Base!$K$3:$K$980,MATCH($K32,Base!$B$3:$B$980,0)),"sem estoque") -> 1554 | F32: =INDEX(Base!$L$3:$L$980,MATCH($K32,Base!$B$3:$B$980,0)) -> 45.805605 | G32: =INDEX(Base!$M$3:$M$980,MATCH($K32,Base!$B$3:$B$980,0)) -> 33.925979 | H32: =INDEX(Base!$N$3:$N$980,MATCH($K32,Base!$B$3:$B$980,0)) -> 15.800198 | I32: =INDEX(Base!$O$3:$O$980,MATCH($K32,Base!$B$3:$B$980,0)) -> 15.800198 | K32: 201010000417Ara
B33: =INDEX(Base!$H$3:$H$980,MATCH($K33,Base!$B$3:$B$980,0)) -> MOLHO STACKER BAG CL BK CX5X1,1KG | C33: =IFERROR(IF(INDEX(Base!$I$3:$I$980,MATCH($K33,Base!$B$3:$B$980,0))="","",INDEX(Base!$I$3:$I$980,MATCH($K33,Base!$B$3:$B$980,0))),"sem fornecedor") -> KERRY | D33: =INDEX(Base!$E$3:$E$980,MATCH($K33,Base!$B$3:$B$980,0)) -> 201010000482 | E33: =IFERROR(INDEX(Base!$K$3:$K$980,MATCH($K33,Base!$B$3:$B$980,0)),"sem estoque") -> 1552 | F33: =INDEX(Base!$L$3:$L$980,MATCH($K33,Base!$B$3:$B$980,0)) -> 71.266771 | G33: =INDEX(Base!$M$3:$M$980,MATCH($K33,Base!$B$3:$B$980,0)) -> 21.77733 | H33: =INDEX(Base!$N$3:$N$980,MATCH($K33,Base!$B$3:$B$980,0)) -> 17.982677 | I33: =INDEX(Base!$O$3:$O$980,MATCH($K33,Base!$B$3:$B$980,0)) -> 17.982677 | K33: 201010000482Ara
B34: =INDEX(Base!$H$3:$H$980,MATCH($K34,Base!$B$3:$B$980,0)) -> MOLHO BARBECUE BAG MP BK CX COM 5,5 KG | C34: =IFERROR(IF(INDEX(Base!$I$3:$I$980,MATCH($K34,Base!$B$3:$B$980,0))="","",INDEX(Base!$I$3:$I$980,MATCH($K34,Base!$B$3:$B$980,0))),"sem fornecedor") -> MECANOPACK | D34: =INDEX(Base!$E$3:$E$980,MATCH($K34,Base!$B$3:$B$980,0)) -> 201010000322 | E34: =IFERROR(INDEX(Base!$K$3:$K$980,MATCH($K34,Base!$B$3:$B$980,0)),"sem estoque") -> 764 | F34: =INDEX(Base!$L$3:$L$980,MATCH($K34,Base!$B$3:$B$980,0)) -> 46.298886 | G34: =INDEX(Base!$M$3:$M$980,MATCH($K34,Base!$B$3:$B$980,0)) -> 16.501477 | H34: =INDEX(Base!$N$3:$N$980,MATCH($K34,Base!$B$3:$B$980,0)) -> 25 | I34: =INDEX(Base!$O$3:$O$980,MATCH($K34,Base!$B$3:$B$980,0)) -> 16.501477 | K34: 201010000322Ara
B35: =INDEX(Base!$H$3:$H$980,MATCH($K35,Base!$B$3:$B$980,0)) -> MAIONESE GRANEL SABOR BACON CX5,5KG | C35: =IFERROR(IF(INDEX(Base!$I$3:$I$980,MATCH($K35,Base!$B$3:$B$980,0))="","",INDEX(Base!$I$3:$I$980,MATCH($K35,Base!$B$3:$B$980,0))),"sem fornecedor") -> KERRY | D35: =INDEX(Base!$E$3:$E$980,MATCH($K35,Base!$B$3:$B$980,0)) -> 201010000406 | E35: =IFERROR(INDEX(Base!$K$3:$K$980,MATCH($K35,Base!$B$3:$B$980,0)),"sem estoque") -> 1214 | F35: =INDEX(Base!$L$3:$L$980,MATCH($K35,Base!$B$3:$B$980,0)) -> 26.497757 | G35: =INDEX(Base!$M$3:$M$980,MATCH($K35,Base!$B$3:$B$980,0)) -> 45.815199 | H35: =INDEX(Base!$N$3:$N$980,MATCH($K35,Base!$B$3:$B$980,0)) -> 36 | I35: =INDEX(Base!$O$3:$O$980,MATCH($K35,Base!$B$3:$B$980,0)) -> 36 | K35: 201010000406Ara
B36: =INDEX(Base!$H$3:$H$980,MATCH($K36,Base!$B$3:$B$980,0)) -> KETCHUP A GRANEL BK HEINZ CX 8X2KG | C36: =IFERROR(IF(INDEX(Base!$I$3:$I$980,MATCH($K36,Base!$B$3:$B$980,0))="","",INDEX(Base!$I$3:$I$980,MATCH($K36,Base!$B$3:$B$980,0))),"sem fornecedor") -> HEINZ | D36: =INDEX(Base!$E$3:$E$980,MATCH($K36,Base!$B$3:$B$980,0)) -> 201010000567 | E36: =IFERROR(INDEX(Base!$K$3:$K$980,MATCH($K36,Base!$B$3:$B$980,0)),"sem estoque") -> 763 | F36: =INDEX(Base!$L$3:$L$980,MATCH($K36,Base!$B$3:$B$980,0)) -> 21.036583 | G36: =INDEX(Base!$M$3:$M$980,MATCH($K36,Base!$B$3:$B$980,0)) -> 36.27015 | H36: =INDEX(Base!$N$3:$N$980,MATCH($K36,Base!$B$3:$B$980,0)) -> 21.631544 | I36: =INDEX(Base!$O$3:$O$980,MATCH($K36,Base!$B$3:$B$980,0)) -> 21.631544 | K36: 201010000567Ara
B37: =INDEX(Base!$H$3:$H$980,MATCH($K37,Base!$B$3:$B$980,0)) -> MOSTARDA HEINZ BK SACHE 2304 5G | C37: =IFERROR(IF(INDEX(Base!$I$3:$I$980,MATCH($K37,Base!$B$3:$B$980,0))="","",INDEX(Base!$I$3:$I$980,MATCH($K37,Base!$B$3:$B$980,0))),"sem fornecedor") -> HEINZ | D37: =INDEX(Base!$E$3:$E$980,MATCH($K37,Base!$B$3:$B$980,0)) -> 201010000616 | E37: =IFERROR(INDEX(Base!$K$3:$K$980,MATCH($K37,Base!$B$3:$B$980,0)),"sem estoque") -> 452 | F37: =INDEX(Base!$L$3:$L$980,MATCH($K37,Base!$B$3:$B$980,0)) -> 14.164926 | G37: =INDEX(Base!$M$3:$M$980,MATCH($K37,Base!$B$3:$B$980,0)) -> 31.909804 | H37: =INDEX(Base!$N$3:$N$980,MATCH($K37,Base!$B$3:$B$980,0)) -> 17.795143 | I37: =INDEX(Base!$O$3:$O$980,MATCH($K37,Base!$B$3:$B$980,0)) -> 17.795143 | K37: 201010000616Ara
B38: =INDEX(Base!$H$3:$H$980,MATCH($K38,Base!$B$3:$B$980,0)) -> MOLHO FURIOSO NCM BK 5.5KG CLEAN | C38: =IFERROR(IF(INDEX(Base!$I$3:$I$980,MATCH($K38,Base!$B$3:$B$980,0))="","",INDEX(Base!$I$3:$I$980,MATCH($K38,Base!$B$3:$B$980,0))),"sem fornecedor") -> KERRY | D38: =INDEX(Base!$E$3:$E$980,MATCH($K38,Base!$B$3:$B$980,0)) -> 201010000324 | E38: =IFERROR(INDEX(Base!$K$3:$K$980,MATCH($K38,Base!$B$3:$B$980,0)),"sem estoque") -> 631 | F38: =INDEX(Base!$L$3:$L$980,MATCH($K38,Base!$B$3:$B$980,0)) -> 14.643601 | G38: =INDEX(Base!$M$3:$M$980,MATCH($K38,Base!$B$3:$B$980,0)) -> 43.090493 | H38: =INDEX(Base!$N$3:$N$980,MATCH($K38,Base!$B$3:$B$980,0)) -> 26.544872 | I38: =INDEX(Base!$O$3:$O$980,MATCH($K38,Base!$B$3:$B$980,0)) -> 26.544872 | K38: 201010000324Ara
B39: =INDEX(Base!$H$3:$H$980,MATCH($K39,Base!$B$3:$B$980,0)) -> MAIONESE SACHET SABOR BACON CX C/304 UND | C39: =IFERROR(IF(INDEX(Base!$I$3:$I$980,MATCH($K39,Base!$B$3:$B$980,0))="","",INDEX(Base!$I$3:$I$980,MATCH($K39,Base!$B$3:$B$980,0))),"sem fornecedor") -> KERRY | D39: =INDEX(Base!$E$3:$E$980,MATCH($K39,Base!$B$3:$B$980,0)) -> 201010000455 | E39: =IFERROR(INDEX(Base!$K$3:$K$980,MATCH($K39,Base!$B$3:$B$980,0)),"sem estoque") -> 193 | F39: =INDEX(Base!$L$3:$L$980,MATCH($K39,Base!$B$3:$B$980,0)) -> 6.2039324 | G39: =INDEX(Base!$M$3:$M$980,MATCH($K39,Base!$B$3:$B$980,0)) -> 31.109301 | H39: =INDEX(Base!$N$3:$N$980,MATCH($K39,Base!$B$3:$B$980,0)) -> 20.287958 | I39: =INDEX(Base!$O$3:$O$980,MATCH($K39,Base!$B$3:$B$980,0)) -> 20.287958 | K39: 201010000455Ara
B40: =INDEX(Base!$H$3:$H$980,MATCH($K40,Base!$B$3:$B$980,0)) -> MOLHO BARBECUE BLISTER BK MP CX COM 144 UND 28G | C40: =IFERROR(IF(INDEX(Base!$I$3:$I$980,MATCH($K40,Base!$B$3:$B$980,0))="","",INDEX(Base!$I$3:$I$980,MATCH($K40,Base!$B$3:$B$980,0))),"sem fornecedor") -> MECANOPACK | D40: =INDEX(Base!$E$3:$E$980,MATCH($K40,Base!$B$3:$B$980,0)) -> 201010000561 | E40: =IFERROR(INDEX(Base!$K$3:$K$980,MATCH($K40,Base!$B$3:$B$980,0)),"sem estoque") -> 64 | F40: =INDEX(Base!$L$3:$L$980,MATCH($K40,Base!$B$3:$B$980,0)) -> 5.0277885 | G40: =INDEX(Base!$M$3:$M$980,MATCH($K40,Base!$B$3:$B$980,0)) -> 12.729255 | H40: =INDEX(Base!$N$3:$N$980,MATCH($K40,Base!$B$3:$B$980,0)) -> 23 | I40: =INDEX(Base!$O$3:$O$980,MATCH($K40,Base!$B$3:$B$980,0)) -> 12.729255 | K40: 201010000561Ara
B41: =INDEX(Base!$H$3:$H$980,MATCH($K41,Base!$B$3:$B$980,0)) -> MOLHO FURIOSO BK NCM CX 144 BLISTER 28G UND | C41: =IFERROR(IF(INDEX(Base!$I$3:$I$980,MATCH($K41,Base!$B$3:$B$980,0))="","",INDEX(Base!$I$3:$I$980,MATCH($K41,Base!$B$3:$B$980,0))),"sem fornecedor") -> KERRY | D41: =INDEX(Base!$E$3:$E$980,MATCH($K41,Base!$B$3:$B$980,0)) -> 201010000562 | E41: =IFERROR(INDEX(Base!$K$3:$K$980,MATCH($K41,Base!$B$3:$B$980,0)),"sem estoque") -> 72 | F41: =INDEX(Base!$L$3:$L$980,MATCH($K41,Base!$B$3:$B$980,0)) -> 4.762533 | G41: =INDEX(Base!$M$3:$M$980,MATCH($K41,Base!$B$3:$B$980,0)) -> 15.118006 | H41: =INDEX(Base!$N$3:$N$980,MATCH($K41,Base!$B$3:$B$980,0)) -> 19.66118 | I41: =INDEX(Base!$O$3:$O$980,MATCH($K41,Base!$B$3:$B$980,0)) -> 15.118006 | K41: 201010000562Ara
B42: =INDEX(Base!$H$3:$H$980,MATCH($K42,Base!$B$3:$B$980,0)) -> MAIONESE VERDE SACHET CX COM 304 UND | C42: =IFERROR(IF(INDEX(Base!$I$3:$I$980,MATCH($K42,Base!$B$3:$B$980,0))="","",INDEX(Base!$I$3:$I$980,MATCH($K42,Base!$B$3:$B$980,0))),"sem fornecedor") -> KERRY | D42: =INDEX(Base!$E$3:$E$980,MATCH($K42,Base!$B$3:$B$980,0)) -> 201010000633 | E42: =IFERROR(INDEX(Base!$K$3:$K$980,MATCH($K42,Base!$B$3:$B$980,0)),"sem estoque") -> 137 | F42: =INDEX(Base!$L$3:$L$980,MATCH($K42,Base!$B$3:$B$980,0)) -> 2.5406528 | G42: =INDEX(Base!$M$3:$M$980,MATCH($K42,Base!$B$3:$B$980,0)) -> 53.92315 | H42: =INDEX(Base!$N$3:$N$980,MATCH($K42,Base!$B$3:$B$980,0)) -> 22.232323 | I42: =INDEX(Base!$O$3:$O$980,MATCH($K42,Base!$B$3:$B$980,0)) -> 22.232323 | K42: 201010000633Ara
... B44: =INDEX(Base!$H$3:$H$980,MATCH($K44,Base!$B$3:$B$980,0)) -> MOSTARDA HEINZ BK BAG 8X2KG | C44: =IFERROR(IF(INDEX(Base!$I$3:$I$980,MATCH($K44,Base!$B$3:$B$980,0))="","",INDEX(Base!$I$3:$I$980,MATCH($K44,Base!$B$3:$B$980,0))),"sem fornecedor") -> HEINZ | D44: =INDEX(Base!$E$3:$E$980,MATCH($K44,Base!$B$3:$B$980,0)) -> 201010000617 | E44: =IFERROR(INDEX(Base!$K$3:$K$980,MATCH($K44,Base!$B$3:$B$980,0)),"sem estoque") -> 108 | F44: =INDEX(Base!$L$3:$L$980,MATCH($K44,Base!$B$3:$B$980,0)) -> 2.5547871 | G44: =INDEX(Base!$M$3:$M$980,MATCH($K44,Base!$B$3:$B$980,0)) -> 42.273581 | H44: =INDEX(Base!$N$3:$N$980,MATCH($K44,Base!$B$3:$B$980,0)) -> 24.930556 | I44: =INDEX(Base!$O$3:$O$980,MATCH($K44,Base!$B$3:$B$980,0)) -> 24.930556 | K44: 201010000617Ara
...

Sheet Jpe
B2: DOH João Pessoa – por Categoria
B5: Categoria / Item | C5: Fornecedor | D5: SAP | E5: Estoque (cx) | F5: Demanda (cx/dia) | G5: DOH | H5: PE | I5: DOH Considerado | J5: Ranking categoria (1 = mais crítica) | K5: Chave
B6: BEBIDAS | E6: =SUMIFS(Base!$K$3:$K$980,Base!$J$3:$J$980,"Jpe",Base!$G$3:$G$980,$B6,Base!$K$3:$K$980,"<>#N/A") -> 5209 | F6: =SUMIFS(Base!$L$3:$L$980,Base!$J$3:$J$980,"Jpe",Base!$G$3:$G$980,$B6) -> 226.35612 | G6: =IFERROR(E6/F6,0) -> 23.012411 | I6: =IFERROR(SUMIFS(Base!$P$3:$P$980,Base!$J$3:$J$980,"Jpe",Base!$G$3:$G$980,$B6)/F6,0) -> 17.2076 | J6: =1+SUMPRODUCT(($K$6:$K$114="")*($I$6:$I$114<I6)) -> 9
B7: =INDEX(Base!$H$3:$H$980,MATCH($K7,Base!$B$3:$B$980,0)) -> SUCO UVA/ MACA NATURAL ONE 180 ML FD C/6UN | C7: =IFERROR(IF(INDEX(Base!$I$3:$I$980,MATCH($K7,Base!$B$3:$B$980,0))="","",INDEX(Base!$I$3:$I$980,MATCH($K7,Base!$B$3:$B$980,0))),"sem fornecedor") -> NATURALONE | D7: =INDEX(Base!$E$3:$E$980,MATCH($K7,Base!$B$3:$B$980,0)) -> 221000000780 | E7: =IFERROR(INDEX(Base!$K$3:$K$980,MATCH($K7,Base!$B$3:$B$980,0)),"sem estoque") -> 2429 | F7: =INDEX(Base!$L$3:$L$980,MATCH($K7,Base!$B$3:$B$980,0)) -> 94.522796 | G7: =INDEX(Base!$M$3:$M$980,MATCH($K7,Base!$B$3:$B$980,0)) -> 25.697505 | H7: =INDEX(Base!$N$3:$N$980,MATCH($K7,Base!$B$3:$B$980,0)) -> 18 | I7: =INDEX(Base!$O$3:$O$980,MATCH($K7,Base!$B$3:$B$980,0)) -> 18 | K7: 221000000780Jpe
B8: =INDEX(Base!$H$3:$H$980,MATCH($K8,Base!$B$3:$B$980,0)) -> SUCO LARANJA COM MACA FD 12X300ML | C8: =IFERROR(IF(INDEX(Base!$I$3:$I$980,MATCH($K8,Base!$B$3:$B$980,0))="","",INDEX(Base!$I$3:$I$980,MATCH($K8,Base!$B$3:$B$980,0))),"sem fornecedor") -> NATURALONE | D8: =INDEX(Base!$E$3:$E$980,MATCH($K8,Base!$B$3:$B$980,0)) -> 221000000541 | E8: =IFERROR(INDEX(Base!$K$3:$K$980,MATCH($K8,Base!$B$3:$B$980,0)),"sem estoque") -> 1154 | F8: =INDEX(Base!$L$3:$L$980,MATCH($K8,Base!$B$3:$B$980,0)) -> 59.08195 | G8: =INDEX(Base!$M$3:$M$980,MATCH($K8,Base!$B$3:$B$980,0)) -> 19.532192 | H8: =INDEX(Base!$N$3:$N$980,MATCH($K8,Base!$B$3:$B$980,0)) -> 15 | I8: =INDEX(Base!$O$3:$O$980,MATCH($K8,Base!$B$3:$B$980,0)) -> 15 | K8: 221000000541Jpe
B9: =INDEX(Base!$H$3:$H$980,MATCH($K9,Base!$B$3:$B$980,0)) -> SUCO UVA MACA 12X300ML PPY/BK | C9: =IFERROR(IF(INDEX(Base!$I$3:$I$980,MATCH($K9,Base!$B$3:$B$980,0))="","",INDEX(Base!$I$3:$I$980,MATCH($K9,Base!$B$3:$B$980,0))),"sem fornecedor") -> NATURALONE | D9: =INDEX(Base!$E$3:$E$980,MATCH($K9,Base!$B$3:$B$980,0)) -> 201080000086 | E9: =IFERROR(INDEX(Base!$K$3:$K$980,MATCH($K9,Base!$B$3:$B$980,0)),"sem estoque") -> 1385 | F9: =INDEX(Base!$L$3:$L$980,MATCH($K9,Base!$B$3:$B$980,0)) -> 59.244769 | G9: =INDEX(Base!$M$3:$M$980,MATCH($K9,Base!$B$3:$B$980,0)) -> 23.377591 | H9: =INDEX(Base!$N$3:$N$980,MATCH($K9,Base!$B$3:$B$980,0)) -> 18 | I9: =INDEX(Base!$O$3:$O$980,MATCH($K9,Base!$B$3:$B$980,0)) -> 18 | K9: 201080000086Jpe
B10: =INDEX(Base!$H$3:$H$980,MATCH($K10,Base!$B$3:$B$980,0)) -> AGUA MINERAL BURGER KING CX 48 UN | C10: =IFERROR(IF(INDEX(Base!$I$3:$I$980,MATCH($K10,Base!$B$3:$B$980,0))="","",INDEX(Base!$I$3:$I$980,MATCH($K10,Base!$B$3:$B$980,0))),"sem fornecedor") -> FLAMIN | D10: =INDEX(Base!$E$3:$E$980,MATCH($K10,Base!$B$3:$B$980,0)) -> 201080000005 | E10: =IFERROR(INDEX(Base!$K$3:$K$980,MATCH($K10,Base!$B$3:$B$980,0)),"sem estoque") -> 241 | F10: =INDEX(Base!$L$3:$L$980,MATCH($K10,Base!$B$3:$B$980,0)) -> 13.506601 | G10: =INDEX(Base!$M$3:$M$980,MATCH($K10,Base!$B$3:$B$980,0)) -> 17.843127 | H10: =INDEX(Base!$N$3:$N$980,MATCH($K10,Base!$B$3:$B$980,0)) -> 31 | I10: =INDEX(Base!$O$3:$O$980,MATCH($K10,Base!$B$3:$B$980,0)) -> 17.843127 | K10: 201080000005Jpe
B11: PÃES | E11: =SUMIFS(Base!$K$3:$K$980,Base!$J$3:$J$980,"Jpe",Base!$G$3:$G$980,$B11,Base!$K$3:$K$980,"<>#N/A") -> 1638 | F11: =SUMIFS(Base!$L$3:$L$980,Base!$J$3:$J$980,"Jpe",Base!$G$3:$G$980,$B11) -> 332.37519 | G11: =IFERROR(E11/F11,0) -> 4.9281657 | I11: =IFERROR(SUMIFS(Base!$P$3:$P$980,Base!$J$3:$J$980,"Jpe",Base!$G$3:$G$980,$B11)/F11,0) -> 4.9281657 | J11: =1+SUMPRODUCT(($K$6:$K$114="")*($I$6:$I$114<I11)) -> 1
B12: =INDEX(Base!$H$3:$H$980,MATCH($K12,Base!$B$3:$B$980,0)) -> PAO BK 5 CL CXG CONG 10500G UNB | C12: =IFERROR(IF(INDEX(Base!$I$3:$I$980,MATCH($K12,Base!$B$3:$B$980,0))="","",INDEX(Base!$I$3:$I$980,MATCH($K12,Base!$B$3:$B$980,0))),"sem fornecedor") -> BIMBO | D12: =INDEX(Base!$E$3:$E$980,MATCH($K12,Base!$B$3:$B$980,0)) -> 201010000575 | E12: =IFERROR(INDEX(Base!$K$3:$K$980,MATCH($K12,Base!$B$3:$B$980,0)),"sem estoque") -> 669 | F12: =INDEX(Base!$L$3:$L$980,MATCH($K12,Base!$B$3:$B$980,0)) -> 113.33855 | G12: =INDEX(Base!$M$3:$M$980,MATCH($K12,Base!$B$3:$B$980,0)) -> 5.9026694 | H12: =INDEX(Base!$N$3:$N$980,MATCH($K12,Base!$B$3:$B$980,0)) -> 7.03 | I12: =INDEX(Base!$O$3:$O$980,MATCH($K12,Base!$B$3:$B$980,0)) -> 5.9026694 | K12: 201010000575Jpe
B13: =INDEX(Base!$H$3:$H$980,MATCH($K13,Base!$B$3:$B$980,0)) -> PAO BK 4 CONG CXG 14900G UNB | C13: =IFERROR(IF(INDEX(Base!$I$3:$I$980,MATCH($K13,Base!$B$3:$B$980,0))="","",INDEX(Base!$I$3:$I$980,MATCH($K13,Base!$B$3:$B$980,0))),"sem fornecedor") -> BIMBO | D13: =INDEX(Base!$E$3:$E$980,MATCH($K13,Base!$B$3:$B$980,0)) -> 201010000262 | E13: =IFERROR(INDEX(Base!$K$3:$K$980,MATCH($K13,Base!$B$3:$B$980,0)),"sem estoque") -> 757 | F13: =INDEX(Base!$L$3:$L$980,MATCH($K13,Base!$B$3:$B$980,0)) -> 192.4504 | G13: =INDEX(Base!$M$3:$M$980,MATCH($K13,Base!$B$3:$B$980,0)) -> 3.933481 | H13: =INDEX(Base!$N$3:$N$980,MATCH($K13,Base!$B$3:$B$980,0)) -> 7.86 | I13: =INDEX(Base!$O$3:$O$980,MATCH($K13,Base!$B$3:$B$980,0)) -> 3.933481 | K13: 201010000262Jpe
B14: =INDEX(Base!$H$3:$H$980,MATCH($K14,Base!$B$3:$B$980,0)) -> PAO SUPREMO BK CONG CX 180 UND | C14: =IFERROR(IF(INDEX(Base!$I$3:$I$980,MATCH($K14,Base!$B$3:$B$980,0))="","",INDEX(Base!$I$3:$I$980,MATCH($K14,Base!$B$3:$B$980,0))),"sem fornecedor") -> BIMBO | D14: =INDEX(Base!$E$3:$E$980,MATCH($K14,Base!$B$3:$B$980,0)) -> 201010000368 | E14: =IFERROR(INDEX(Base!$K$3:$K$980,MATCH($K14,Base!$B$3:$B$980,0)),"sem estoque") -> 119 | F14: =INDEX(Base!$L$3:$L$980,MATCH($K14,Base!$B$3:$B$980,0)) -> 19.032024 | G14: =INDEX(Base!$M$3:$M$980,MATCH($K14,Base!$B$3:$B$980,0)) -> 6.2526194 | H14: =INDEX(Base!$N$3:$N$980,MATCH($K14,Base!$B$3:$B$980,0)) -> 10 | I14: =INDEX(Base!$O$3:$O$980,MATCH($K14,Base!$B$3:$B$980,0)) -> 6.2526194 | K14: 201010000368Jpe
B15: =INDEX(Base!$H$3:$H$980,MATCH($K15,Base!$B$3:$B$980,0)) -> PAO BRIOCHE BK CX 192 UND | C15: =IFERROR(IF(INDEX(Base!$I$3:$I$980,MATCH($K15,Base!$B$3:$B$980,0))="","",INDEX(Base!$I$3:$I$980,MATCH($K15,Base!$B$3:$B$980,0))),"sem fornecedor") -> BIMBO | D15: =INDEX(Base!$E$3:$E$980,MATCH($K15,Base!$B$3:$B$980,0)) -> 201010000492 | E15: =IFERROR(INDEX(Base!$K$3:$K$980,MATCH($K15,Base!$B$3:$B$980,0)),"sem estoque") -> 93 | F15: =INDEX(Base!$L$3:$L$980,MATCH($K15,Base!$B$3:$B$980,0)) -> 7.5542095 | G15: =INDEX(Base!$M$3:$M$980,MATCH($K15,Base!$B$3:$B$980,0)) -> 12.311017 | H15: =INDEX(Base!$N$3:$N$980,MATCH($K15,Base!$B$3:$B$980,0)) -> 15 | I15: =INDEX(Base!$O$3:$O$980,MATCH($K15,Base!$B$3:$B$980,0)) -> 12.311017 | K15: 201010000492Jpe
B16: PROTEINAS | E16: =SUMIFS(Base!$K$3:$K$980,Base!$J$3:$J$980,"Jpe",Base!$G$3:$G$980,$B16,Base!$K$3:$K$980,"<>#N/A") -> 7001 | F16: =SUMIFS(Base!$L$3:$L$980,Base!$J$3:$J$980,"Jpe",Base!$G$3:$G$980,$B16) -> 460.34046 | G16: =IFERROR(E16/F16,0) -> 15.208309 | I16: =IFERROR(SUMIFS(Base!$P$3:$P$980,Base!$J$3:$J$980,"Jpe",Base!$G$3:$G$980,$B16)/F16,0) -> 9.6034716 | J16: =1+SUMPRODUCT(($K$6:$K$114="")*($I$6:$I$114<I16)) -> 2
B17: =INDEX(Base!$H$3:$H$980,MATCH($K17,Base!$B$3:$B$980,0)) -> CHICKEN JR CLEAN BK CX 9,88KG | C17: =IFERROR(IF(INDEX(Base!$I$3:$I$980,MATCH($K17,Base!$B$3:$B$980,0))="","",INDEX(Base!$I$3:$I$980,MATCH($K17,Base!$B$3:$B$980,0))),"sem fornecedor") -> SEARA | D17: =INDEX(Base!$E$3:$E$980,MATCH($K17,Base!$B$3:$B$980,0)) -> 201010000218 | E17: =IFERROR(INDEX(Base!$K$3:$K$980,MATCH($K17,Base!$B$3:$B$980,0)),"sem estoque") -> 1202 | F17: =INDEX(Base!$L$3:$L$980,MATCH($K17,Base!$B$3:$B$980,0)) -> 64.274052 | G17: =INDEX(Base!$M$3:$M$980,MATCH($K17,Base!$B$3:$B$980,0)) -> 18.701171 | H17: =INDEX(Base!$N$3:$N$980,MATCH($K17,Base!$B$3:$B$980,0)) -> 15 | I17: =INDEX(Base!$O$3:$O$980,MATCH($K17,Base!$B$3:$B$980,0)) -> 15 | K17: 201010000218Jpe
B18: =INDEX(Base!$H$3:$H$980,MATCH($K18,Base!$B$3:$B$980,0)) -> CARNE CONG MOIDA WHOPPER BK CX 17,2KG | C18: =IFERROR(IF(INDEX(Base!$I$3:$I$980,MATCH($K18,Base!$B$3:$B$980,0))="","",INDEX(Base!$I$3:$I$980,MATCH($K18,Base!$B$3:$B$980,0))),"sem fornecedor") -> JBS | D18: =INDEX(Base!$E$3:$E$980,MATCH($K18,Base!$B$3:$B$980,0)) -> 201010000209 | E18: =IFERROR(INDEX(Base!$K$3:$K$980,MATCH($K18,Base!$B$3:$B$980,0)),"sem estoque") -> 1769 | F18: =INDEX(Base!$L$3:$L$980,MATCH($K18,Base!$B$3:$B$980,0)) -> 122.47791 | G18: =INDEX(Base!$M$3:$M$980,MATCH($K18,Base!$B$3:$B$980,0)) -> 14.44342 | H18: =INDEX(Base!$N$3:$N$980,MATCH($K18,Base!$B$3:$B$980,0)) -> 7 | I18: =INDEX(Base!$O$3:$O$980,MATCH($K18,Base!$B$3:$B$980,0)) -> 7 | K18: 201010000209Jpe
B19: =INDEX(Base!$H$3:$H$980,MATCH($K19,Base!$B$3:$B$980,0)) -> CARNE HB CONG BKC CX COM 18,7 KG | C19: =IFERROR(IF(INDEX(Base!$I$3:$I$980,MATCH($K19,Base!$B$3:$B$980,0))="","",INDEX(Base!$I$3:$I$980,MATCH($K19,Base!$B$3:$B$980,0))),"sem fornecedor") -> JBS | D19: =INDEX(Base!$E$3:$E$980,MATCH($K19,Base!$B$3:$B$980,0)) -> 201010000645 | E19: =IFERROR(INDEX(Base!$K$3:$K$980,MATCH($K19,Base!$B$3:$B$980,0)),"sem estoque") -> 2623 | F19: =INDEX(Base!$L$3:$L$980,MATCH($K19,Base!$B$3:$B$980,0)) -> 192.93754 | G19: =INDEX(Base!$M$3:$M$980,MATCH($K19,Base!$B$3:$B$980,0)) -> 13.595073 | H19: =INDEX(Base!$N$3:$N$980,MATCH($K19,Base!$B$3:$B$980,0)) -> 7 | I19: =INDEX(Base!$O$3:$O$980,MATCH($K19,Base!$B$3:$B$980,0)) -> 7 | K19: 201010000645Jpe
B20: =INDEX(Base!$H$3:$H$980,MATCH($K20,Base!$B$3:$B$980,0)) -> CHICKEN NUGGETS CX COM 12 KG | C20: =IFERROR(IF(INDEX(Base!$I$3:$I$980,MATCH($K20,Base!$B$3:$B$980,0))="","",INDEX(Base!$I$3:$I$980,MATCH($K20,Base!$B$3:$B$980,0))),"sem fornecedor") -> SEARA | D20: =INDEX(Base!$E$3:$E$980,MATCH($K20,Base!$B$3:$B$980,0)) -> 201010000565 | E20: =IFERROR(INDEX(Base!$K$3:$K$980,MATCH($K20,Base!$B$3:$B$980,0)),"sem estoque") -> 532 | F20: =INDEX(Base!$L$3:$L$980,MATCH($K20,Base!$B$3:$B$980,0)) -> 33.06361 | G20: =INDEX(Base!$M$3:$M$980,MATCH($K20,Base!$B$3:$B$980,0)) -> 16.090197 | H20: =INDEX(Base!$N$3:$N$980,MATCH($K20,Base!$B$3:$B$980,0)) -> 24 | I20: =INDEX(Base!$O$3:$O$980,MATCH($K20,Base!$B$3:$B$980,0)) -> 16.090197 | K20: 201010000565Jpe
B21: =INDEX(Base!$H$3:$H$980,MATCH($K21,Base!$B$3:$B$980,0)) -> BACON PRONTO CONG 1187 UND CX 4KG DIS | C21: =IFERROR(IF(INDEX(Base!$I$3:$I$980,MATCH($K21,Base!$B$3:$B$980,0))="","",INDEX(Base!$I$3:$I$980,MATCH($K21,Base!$B$3:$B$980,0))),"sem fornecedor") -> SEARA2 | D21: =INDEX(Base!$E$3:$E$980,MATCH($K21,Base!$B$3:$B$980,0)) -> 201010000684 | E21: =IFERROR(INDEX(Base!$K$3:$K$980,MATCH($K21,Base!$B$3:$B$980,0)),"sem estoque") -> 504 | F21: =INDEX(Base!$L$3:$L$980,MATCH($K21,Base!$B$3:$B$980,0)) -> 31.516889 | G21: =INDEX(Base!$M$3:$M$980,MATCH($K21,Base!$B$3:$B$980,0)) -> 15.991426 | H21: =INDEX(Base!$N$3:$N$980,MATCH($K21,Base!$B$3:$B$980,0)) -> 15 | I21: =INDEX(Base!$O$3:$O$980,MATCH($K21,Base!$B$3:$B$980,0)) -> 15 | K21: 201010000684Jpe
B22: =INDEX(Base!$H$3:$H$980,MATCH($K22,Base!$B$3:$B$980,0)) -> BACON BK ASS CUBOS CX 2X1KG | C22: =IFERROR(IF(INDEX(Base!$I$3:$I$980,MATCH($K22,Base!$B$3:$B$980,0))="","",INDEX(Base!$I$3:$I$980,MATCH($K22,Base!$B$3:$B$980,0))),"sem fornecedor") -> MINERVA | D22: =INDEX(Base!$E$3:$E$980,MATCH($K22,Base!$B$3:$B$980,0)) -> 201010000402 | E22: =IFERROR(INDEX(Base!$K$3:$K$980,MATCH($K22,Base!$B$3:$B$980,0)),"sem estoque") -> 200 | F22: =INDEX(Base!$L$3:$L$980,MATCH($K22,Base!$B$3:$B$980,0)) -> 7.5029319 | G22: =INDEX(Base!$M$3:$M$980,MATCH($K22,Base!$B$3:$B$980,0)) -> 26.656246 | H22: =INDEX(Base!$N$3:$N$980,MATCH($K22,Base!$B$3:$B$980,0)) -> 15 | I22: =INDEX(Base!$O$3:$O$980,MATCH($K22,Base!$B$3:$B$980,0)) -> 15 | K22: 201010000402Jpe
B23: =INDEX(Base!$H$3:$H$980,MATCH($K23,Base!$B$3:$B$980,0)) -> TENDER CRISPY FILE NOVO BK CX 4X2,5 KG | C23: =IFERROR(IF(INDEX(Base!$I$3:$I$980,MATCH($K23,Base!$B$3:$B$980,0))="","",INDEX(Base!$I$3:$I$980,MATCH($K23,Base!$B$3:$B$980,0))),"sem fornecedor") -> BRF | D23: =INDEX(Base!$E$3:$E$980,MATCH($K23,Base!$B$3:$B$980,0)) -> 201010000539 | E23: =IFERROR(INDEX(Base!$K$3:$K$980,MATCH($K23,Base!$B$3:$B$980,0)),"sem estoque") -> 88 | F23: =INDEX(Base!$L$3:$L$980,MATCH($K23,Base!$B$3:$B$980,0)) -> 5.8456295 | G23: =INDEX(Base!$M$3:$M$980,MATCH($K23,Base!$B$3:$B$980,0)) -> 15.053982 | H23: =INDEX(Base!$N$3:$N$980,MATCH($K23,Base!$B$3:$B$980,0)) -> 18 | I23: =INDEX(Base!$O$3:$O$980,MATCH($K23,Base!$B$3:$B$980,0)) -> 15.053982 | K23: 201010000539Jpe
B24: =INDEX(Base!$H$3:$H$980,MATCH($K24,Base!$B$3:$B$980,0)) -> HAMBURGUER REBEL SABOR PICANHA CX 122 UND 12KG | C24: =IFERROR(IF(INDEX(Base!$I$3:$I$980,MATCH($K24,Base!$B$3:$B$980,0))="","",INDEX(Base!$I$3:$I$980,MATCH($K24,Base!$B$3:$B$980,0))),"sem fornecedor") -> PLANTPLUS2 | D24: =INDEX(Base!$E$3:$E$980,MATCH($K24,Base!$B$3:$B$980,0)) -> 201010000654 | E24: =IFERROR(INDEX(Base!$K$3:$K$980,MATCH($K24,Base!$B$3:$B$980,0)),"sem estoque") -> 83 | F24: =INDEX(Base!$L$3:$L$980,MATCH($K24,Base!$B$3:$B$980,0)) -> 2.7218898 | G24: =INDEX(Base!$M$3:$M$980,MATCH($K24,Base!$B$3:$B$980,0)) -> 30.493519 | H24: =INDEX(Base!$N$3:$N$980,MATCH($K24,Base!$B$3:$B$980,0)) -> 16 | I24: =INDEX(Base!$O$3:$O$980,MATCH($K24,Base!$B$3:$B$980,0)) -> 16 | K24: 201010000654Jpe
B25: LÁCTEOS | E25: =SUMIFS(Base!$K$3:$K$980,Base!$J$3:$J$980,"Jpe",Base!$G$3:$G$980,$B25,Base!$K$3:$K$980,"<>#N/A") -> 3631 | F25: =SUMIFS(Base!$L$3:$L$980,Base!$J$3:$J$980,"Jpe",Base!$G$3:$G$980,$B25) -> 115.05128 | G25: =IFERROR(E25/F25,0) -> 31.559841 | I25: =IFERROR(SUMIFS(Base!$P$3:$P$980,Base!$J$3:$J$980,"Jpe",Base!$G$3:$G$980,$B25)/F25,0) -> 12.350611 | J25: =1+SUMPRODUCT(($K$6:$K$114="")*($I$6:$I$114<I25)) -> 4
B26: =INDEX(Base!$H$3:$H$980,MATCH($K26,Base!$B$3:$B$980,0)) -> BEBIDA LACTEA UHT BAUNILHA BK 10 L X 2 UN | C26: =IFERROR(IF(INDEX(Base!$I$3:$I$980,MATCH($K26,Base!$B$3:$B$980,0))="","",INDEX(Base!$I$3:$I$980,MATCH($K26,Base!$B$3:$B$980,0))),"sem fornecedor") -> POLENGHI2 | D26: =INDEX(Base!$E$3:$E$980,MATCH($K26,Base!$B$3:$B$980,0)) -> 241000000044 | E26: =IFERROR(INDEX(Base!$K$3:$K$980,MATCH($K26,Base!$B$3:$B$980,0)),"sem estoque") -> 2049 | F26: =INDEX(Base!$L$3:$L$980,MATCH($K26,Base!$B$3:$B$980,0)) -> 5.0217349 | G26: =INDEX(Base!$M$3:$M$980,MATCH($K26,Base!$B$3:$B$980,0)) -> 408.02632 | H26: =INDEX(Base!$N$3:$N$980,MATCH($K26,Base!$B$3:$B$980,0)) -> 12.5 | I26: =INDEX(Base!$O$3:$O$980,MATCH($K26,Base!$B$3:$B$980,0)) -> 12.5 | K26: 241000000044Jpe
